<?xml version="1.0" ?>
<!-- =================================================================================== -->
<!-- |    This document was autogenerated by xacro from /mnt/STORAGE/Dropbox/Personal/Programming/Bioloid/Linux/ROS/catkin_ws/src/bioloid_master/urdf/bioloid.xacro | -->
<!-- |    EDITING THIS FILE BY HAND IS NOT RECOMMENDED                                 | -->
<!-- =================================================================================== -->
<robot name="bioloid" xmlns:xacro="http://www.ros.org/wiki/xacro">
  <!-- Select one and only one of the following include files -->
  <!-- 1) Standard parts of Bioloid Comprehensive humanoid with 18 AX-12+ servos, which have been replaced in custom version -->
  <!--    When using this URDF, ensure a transform from odom to base_link is being published -->
  <!-- <xacro:include filename="$(find bioloid_master)/urdf/bioloid_std_parts.xacro" ns="std_parts"/> -->
  <!-- 2) Custom parts of modified Bioloid Comprehensive humanoid, with CM-5 replaced by PC and custom sensors -->
  <!--    When using this URDF, ensure a transform from odom to imu_link is being published -->
  <!-- IMU -->
  <joint name="imu_to_base_joint" type="fixed">
    <parent link="imu_link"/>
    <origin rpy="0 0 0" xyz="0.01 0 0.0788"/>
    <child link="base_link"/>
  </joint>
  <link name="imu_link">
    <visual>
      <geometry>
        <box size="0.04 0.02 0.005"/>
      </geometry>
      <material name="green">
        <color rgba="0.0 1.0 0.0 1.0"/>
      </material>
    </visual>
    <!--<inertial>
            <origin xyz="0 0 0"/>
            <mass value="1.0"/>
            <inertia  ixx="0.001" ixy="0.0"  ixz="0.0"  iyy="0.001"  iyz="0.0"  izz="0.001"/>
        </inertial>-->
  </link>
  <!-- Camera -->
  <!--<joint name="camera_joint" type="fixed">
        <origin xyz="0 0 0.075" rpy="${pi/2} 0 ${pi/2}"/>
        <parent link="base_link"/>
        <child link="camera_link"/>
    </joint>
    <link name="camera_link">-->
  <!--<visual>
            <geometry>
                <box size="0.01 0.01 0.01"/>
            </geometry>
            <material name="black">
                <color rgba="0.0 0.0 0.0 1.0"/>
            </material>
        </visual>
        <inertial>
            <origin xyz="0 0 0"/>
            <mass value="1.0"/>
            <inertia  ixx="0.001" ixy="0.0"  ixz="0.0"  iyy="0.001"  iyz="0.0"  izz="0.001"/>
        </inertial>-->
  <!--</link>-->
  <!-- Head -->
  <joint name="head_joint" type="fixed">
    <origin rpy="0 0 0" xyz="0 0 0.058"/>
    <parent link="base_link"/>
    <child link="head_link"/>
  </joint>
  <link name="head_link">
    <visual>
      <geometry>
        <mesh filename="file:///mnt/STORAGE/Dropbox/Personal/Programming/Bioloid/Linux/ROS/catkin_ws/src/bioloid_master/../../assets/cad/FP04-F5_FCD-Conv_BDR-Col.dae" scale="0.001 0.001 0.001"/>
      </geometry>
      <origin rpy="1.570795 0 -1.570795" xyz="0 0 0"/>
    </visual>
    <visual>
      <geometry>
        <mesh filename="file:///mnt/STORAGE/Dropbox/Personal/Programming/Bioloid/Linux/ROS/catkin_ws/src/bioloid_master/../../assets/cad/FP04-F10_FCD-Conv_BDR-Col.dae" scale="0.001 0.001 0.001"/>
      </geometry>
      <origin rpy="1.570795 0 -1.570795" xyz="0 0 -0.0342"/>
    </visual>
    <visual>
      <geometry>
        <mesh filename="file:///mnt/STORAGE/Dropbox/Personal/Programming/Bioloid/Linux/ROS/catkin_ws/src/bioloid_master/../../assets/cad/RaspPiB_plus_3d_step_V10_FCD-Conv.dae" scale="0.001 0.001 0.001"/>
      </geometry>
      <origin rpy="-1.570795 0 -1.570795" xyz="-0.008 0 0"/>
    </visual>
    <visual>
      <geometry>
        <mesh filename="file:///mnt/STORAGE/Dropbox/Personal/Programming/Bioloid/Linux/ROS/catkin_ws/src/bioloid_master/../../assets/cad/USB2AX-v3.1_FCD-Conv_BDR-Col.dae" scale="0.001 0.001 0.001"/>
      </geometry>
      <origin rpy="0 1.570795 0" xyz="-0.0075 -0.0601 -0.001"/>
    </visual>
    <collision name="head_bracket_collision">
      <origin xyz="-0.009 0 0"/>
      <geometry>
        <box size="0.0405 0.029 0.083"/>
      </geometry>
    </collision>
    <collision name="head_spacer_collision">
      <origin xyz="0 0 -0.0342"/>
      <geometry>
        <box size="0.0251 0.0383 0.0041"/>
      </geometry>
    </collision>
    <collision name="raspberry_pi_collision">
      <origin xyz="-0.0023 -0.0008 0.0008"/>
      <geometry>
        <box size="0.021 0.087 0.058"/>
      </geometry>
    </collision>
    <collision name="usb2ax_collision">
      <origin xyz="-0.0042 -0.05355 -0.001"/>
      <geometry>
        <box size="0.00661 0.037 0.0151"/>
      </geometry>
    </collision>
    <inertial>
      <origin xyz="0 0 0"/>
      <mass value="1.0"/>
      <inertia ixx="0.001" ixy="0.0" ixz="0.0" iyy="0.001" iyz="0.0" izz="0.001"/>
    </inertial>
  </link>
  <!-- CPU case -->
  <joint name="cpu_case_joint" type="fixed">
    <origin rpy="0 0 0" xyz="0 0 0.058"/>
    <parent link="base_link"/>
    <child link="cpu_case_link"/>
  </joint>
  <link name="cpu_case_link">
    <visual>
      <origin xyz="0 0 0"/>
      <geometry>
        <box size="0.026 0.092 0.063"/>
      </geometry>
      <material name="smoke_grey_transp">
        <color rgba="0.2 0.2 0.2 0.8"/>
      </material>
    </visual>
    <collision name="cpu_case_collision">
      <origin xyz="0 0 0"/>
      <geometry>
        <box size="0.026 0.092 0.063"/>
      </geometry>
    </collision>
    <inertial>
      <origin xyz="0 0 0"/>
      <mass value="1.0"/>
      <inertia ixx="0.001" ixy="0.0" ixz="0.0" iyy="0.001" iyz="0.0" izz="0.001"/>
    </inertial>
  </link>
  <!-- Torso -->
  <link name="torso_link">
    <visual>
      <geometry>
        <mesh filename="file:///mnt/STORAGE/Dropbox/Personal/Programming/Bioloid/Linux/ROS/catkin_ws/src/bioloid_master/../../assets/cad/BPF-CHEST-F_FCD-Conv_BDR-Col.dae" scale="0.001 0.001 0.001"/>
      </geometry>
      <origin rpy="1.570795 0 0"/>
    </visual>
    <visual>
      <geometry>
        <mesh filename="file:///mnt/STORAGE/Dropbox/Personal/Programming/Bioloid/Linux/ROS/catkin_ws/src/bioloid_master/../../assets/cad/BPF-CHEST-B_FCD-Conv_BDR-Col.dae" scale="0.001 0.001 0.001"/>
      </geometry>
      <origin rpy="1.570795 0 0"/>
    </visual>
    <visual>
      <geometry>
        <mesh filename="file:///mnt/STORAGE/Dropbox/Personal/Programming/Bioloid/Linux/ROS/catkin_ws/src/bioloid_master/../../assets/cad/Backpack-DX_FCD-Conv_BDR-Col.dae" scale="0.001 0.001 0.001"/>
      </geometry>
      <origin rpy="0 0 1.570795" xyz="0 0.019 -0.0145"/>
    </visual>
    <visual>
      <geometry>
        <mesh filename="file:///mnt/STORAGE/Dropbox/Personal/Programming/Bioloid/Linux/ROS/catkin_ws/src/bioloid_master/../../assets/cad/Battery-Turnigy-2200mAh_FCD-Conv_BDR-Col.dae" scale="0.001 0.001 0.001"/>
      </geometry>
      <origin rpy="0 1.570795 1.570795" xyz="0 0.032 -0.008"/>
    </visual>
    <!-- Motor 1 -->
    <visual>
      <geometry>
        <mesh filename="file:///mnt/STORAGE/Dropbox/Personal/Programming/Bioloid/Linux/ROS/catkin_ws/src/bioloid_master/../../assets/cad/AX-12_FCD-Conv_BDR-Col.dae" scale="0.001 0.001 0.001"/>
      </geometry>
      <origin rpy="1.570795 0 -1.570795" xyz="-0.032 0 0"/>
    </visual>
    <visual>
      <geometry>
        <mesh filename="file:///mnt/STORAGE/Dropbox/Personal/Programming/Bioloid/Linux/ROS/catkin_ws/src/bioloid_master/../../assets/cad/FP04-F3_FCD-Conv_BDR-Col.dae" scale="0.001 0.001 0.001"/>
      </geometry>
      <origin rpy="3.14159 -1.570795 0" xyz="-0.032 0.019 -0.0145"/>
    </visual>
    <!-- Motor 2 -->
    <visual>
      <geometry>
        <mesh filename="file:///mnt/STORAGE/Dropbox/Personal/Programming/Bioloid/Linux/ROS/catkin_ws/src/bioloid_master/../../assets/cad/AX-12_FCD-Conv_BDR-Col.dae" scale="0.001 0.001 0.001"/>
      </geometry>
      <origin rpy="1.570795 0 1.570795" xyz="0.032 0 0"/>
    </visual>
    <visual>
      <geometry>
        <mesh filename="file:///mnt/STORAGE/Dropbox/Personal/Programming/Bioloid/Linux/ROS/catkin_ws/src/bioloid_master/../../assets/cad/FP04-F3_FCD-Conv_BDR-Col.dae" scale="0.001 0.001 0.001"/>
      </geometry>
      <origin rpy="3.14159 -1.570795 0" xyz="0.032 0.019 -0.0145"/>
    </visual>
    <visual>
      <geometry>
        <mesh filename="file:///mnt/STORAGE/Dropbox/Personal/Programming/Bioloid/Linux/ROS/catkin_ws/src/bioloid_master/../../assets/cad/FP04-F8_FCD-Conv_BDR-Col.dae" scale="0.001 0.001 0.001"/>
      </geometry>
      <origin rpy="-1.570795 0 1.570795" xyz="0 0.0255 -0.0465"/>
    </visual>
    <visual>
      <geometry>
        <mesh filename="file:///mnt/STORAGE/Dropbox/Personal/Programming/Bioloid/Linux/ROS/catkin_ws/src/bioloid_master/../../assets/cad/FP04-F8_FCD-Conv_BDR-Col.dae" scale="0.001 0.001 0.001"/>
      </geometry>
      <origin rpy="1.570795 0 1.570795" xyz="0 0.0255 -0.0843"/>
    </visual>
    <!-- Motor 7 -->
    <visual>
      <geometry>
        <mesh filename="file:///mnt/STORAGE/Dropbox/Personal/Programming/Bioloid/Linux/ROS/catkin_ws/src/bioloid_master/../../assets/cad/AX-12_FCD-Conv_BDR-Col.dae" scale="0.001 0.001 0.001"/>
      </geometry>
      <origin rpy="0 3.14159 0" xyz="-0.033 0.016 -0.0655"/>
    </visual>
    <!-- Motor 8 -->
    <visual>
      <geometry>
        <mesh filename="file:///mnt/STORAGE/Dropbox/Personal/Programming/Bioloid/Linux/ROS/catkin_ws/src/bioloid_master/../../assets/cad/AX-12_FCD-Conv_BDR-Col.dae" scale="0.001 0.001 0.001"/>
      </geometry>
      <origin rpy="0 3.14159 0" xyz="0.033 0.016 -0.0655"/>
    </visual>
    <collision name="torso_collision_top">
      <origin xyz="0 0.0075 -0.015"/>
      <geometry>
        <box size="0.103 0.066 0.0635"/>
      </geometry>
    </collision>
    <collision name="Backpack-DX_collision">
      <origin xyz="0 0.041 -0.0145"/>
      <geometry>
        <box size="0.09 0.0441 0.058"/>
      </geometry>
    </collision>
    <collision name="Battery-Turnigy-2200mAh_collision">
      <origin xyz="0 0.04425 -0.008"/>
      <geometry>
        <box size="0.108 0.0246 0.036"/>
      </geometry>
    </collision>
    <collision name="Battery-Turnigy-2200mAh_collision_lead">
      <origin xyz="-0.0515 0.04425 -0.031"/>
      <geometry>
        <box size="0.0041 0.0246 0.01"/>
      </geometry>
    </collision>
    <collision name="torso_collision_bottom">
      <origin xyz="0 0.00625 -0.0648"/>
      <geometry>
        <box size="0.099 0.065 0.043"/>
      </geometry>
    </collision>
    <inertial>
      <origin xyz="0 0 0"/>
      <mass value="1.0"/>
      <inertia ixx="0.001" ixy="0.0" ixz="0.0" iyy="0.001" iyz="0.0" izz="0.001"/>
    </inertial>
  </link>
  <!-- Right foot -->
  <link name="right_foot_link">
    <visual>
      <geometry>
        <mesh filename="file:///mnt/STORAGE/Dropbox/Personal/Programming/Bioloid/Linux/ROS/catkin_ws/src/bioloid_master/../../assets/cad/FP04-F12_FCD-Conv_BDR-Col.dae" scale="0.001 0.001 0.001"/>
      </geometry>
      <origin rpy="0 -1.570795 0" xyz="0 0.0235 -0.016"/>
    </visual>
    <!-- FSR 0 -->
    <visual>
      <geometry>
        <mesh filename="file:///mnt/STORAGE/Dropbox/Personal/Programming/Bioloid/Linux/ROS/catkin_ws/src/bioloid_master/../../assets/cad/34-47021_FSR_400_Short_Tail_FCD-Conv_BDR-Col.dae" scale="0.001 0.001 0.001"/>
      </geometry>
      <origin rpy="3.14159 0 0" xyz="0.022 0.0319 -0.039"/>
    </visual>
    <!-- FSR 1 -->
    <visual>
      <geometry>
        <mesh filename="file:///mnt/STORAGE/Dropbox/Personal/Programming/Bioloid/Linux/ROS/catkin_ws/src/bioloid_master/../../assets/cad/34-47021_FSR_400_Short_Tail_FCD-Conv_BDR-Col.dae" scale="0.001 0.001 0.001"/>
      </geometry>
      <origin rpy="3.14159 0 0" xyz="-0.022 0.0319 -0.039"/>
    </visual>
    <!-- FSR 2 -->
    <visual>
      <geometry>
        <mesh filename="file:///mnt/STORAGE/Dropbox/Personal/Programming/Bioloid/Linux/ROS/catkin_ws/src/bioloid_master/../../assets/cad/34-47021_FSR_400_Short_Tail_FCD-Conv_BDR-Col.dae" scale="0.001 0.001 0.001"/>
      </geometry>
      <origin rpy="3.14159 3.14159 0" xyz="-0.022 0.0319 0.007"/>
    </visual>
    <collision name="right_foot_collision">
      <origin xyz="0 0.0277 -0.016"/>
      <geometry>
        <box size="0.061 0.009 0.101"/>
      </geometry>
    </collision>
    <inertial>
      <origin xyz="0 0 0"/>
      <mass value="1.0"/>
      <inertia ixx="0.001" ixy="0.0" ixz="0.0" iyy="0.001" iyz="0.0" izz="0.001"/>
    </inertial>
  </link>
  <!-- Left foot -->
  <link name="left_foot_link">
    <visual>
      <geometry>
        <mesh filename="file:///mnt/STORAGE/Dropbox/Personal/Programming/Bioloid/Linux/ROS/catkin_ws/src/bioloid_master/../../assets/cad/FP04-F12_FCD-Conv_BDR-Col.dae" scale="0.001 0.001 0.001"/>
      </geometry>
      <origin rpy="3.14159 1.570795 0" xyz="0 -0.0235 0.016"/>
    </visual>
    <!-- FSR 3 -->
    <visual>
      <geometry>
        <mesh filename="file:///mnt/STORAGE/Dropbox/Personal/Programming/Bioloid/Linux/ROS/catkin_ws/src/bioloid_master/../../assets/cad/34-47021_FSR_400_Short_Tail_FCD-Conv_BDR-Col.dae" scale="0.001 0.001 0.001"/>
      </geometry>
      <origin rpy="0 0 0" xyz="-0.022 -0.0319 0.039"/>
    </visual>
    <!-- FSR 4 -->
    <visual>
      <geometry>
        <mesh filename="file:///mnt/STORAGE/Dropbox/Personal/Programming/Bioloid/Linux/ROS/catkin_ws/src/bioloid_master/../../assets/cad/34-47021_FSR_400_Short_Tail_FCD-Conv_BDR-Col.dae" scale="0.001 0.001 0.001"/>
      </geometry>
      <origin rpy="0 0 0" xyz="0.022 -0.0319 0.039"/>
    </visual>
    <!-- FSR 5 -->
    <visual>
      <geometry>
        <mesh filename="file:///mnt/STORAGE/Dropbox/Personal/Programming/Bioloid/Linux/ROS/catkin_ws/src/bioloid_master/../../assets/cad/34-47021_FSR_400_Short_Tail_FCD-Conv_BDR-Col.dae" scale="0.001 0.001 0.001"/>
      </geometry>
      <origin rpy="0 3.14159 0" xyz="0.022 -0.0319 -0.007"/>
    </visual>
    <collision name="left_foot_collision">
      <origin xyz="0 -0.0277 0.016"/>
      <geometry>
        <box size="0.061 0.009 0.101"/>
      </geometry>
    </collision>
    <inertial>
      <origin xyz="0 0 0"/>
      <mass value="1.0"/>
      <inertia ixx="0.001" ixy="0.0" ixz="0.0" iyy="0.001" iyz="0.0" izz="0.001"/>
    </inertial>
  </link>
  <!-- Import gazebo_ros_control plugin -->
  <gazebo>
    <plugin filename="libgazebo_ros_control.so" name="gazebo_ros_control">
      <robotNamespace>/</robotNamespace>
      <robotSimType>gazebo_ros_control/DefaultRobotHWSim</robotSimType>
    </plugin>
  </gazebo>
  <transmission name="right_shoulder_swing_joint_tran">
    <type>transmission_interface/SimpleTransmission</type>
    <joint name="right_shoulder_swing_joint">
      <hardwareInterface>EffortJointInterface</hardwareInterface>
    </joint>
    <actuator name="right_shoulder_swing_joint_motor">
      <hardwareInterface>EffortJointInterface</hardwareInterface>
      <mechanicalReduction>1</mechanicalReduction>
    </actuator>
  </transmission>
  <transmission name="left_shoulder_swing_joint_tran">
    <type>transmission_interface/SimpleTransmission</type>
    <joint name="left_shoulder_swing_joint">
      <hardwareInterface>EffortJointInterface</hardwareInterface>
    </joint>
    <actuator name="left_shoulder_swing_joint_motor">
      <hardwareInterface>EffortJointInterface</hardwareInterface>
      <mechanicalReduction>1</mechanicalReduction>
    </actuator>
  </transmission>
  <transmission name="right_shoulder_lateral_joint_tran">
    <type>transmission_interface/SimpleTransmission</type>
    <joint name="right_shoulder_lateral_joint">
      <hardwareInterface>EffortJointInterface</hardwareInterface>
    </joint>
    <actuator name="right_shoulder_lateral_joint_motor">
      <hardwareInterface>EffortJointInterface</hardwareInterface>
      <mechanicalReduction>1</mechanicalReduction>
    </actuator>
  </transmission>
  <transmission name="left_shoulder_lateral_joint_tran">
    <type>transmission_interface/SimpleTransmission</type>
    <joint name="left_shoulder_lateral_joint">
      <hardwareInterface>EffortJointInterface</hardwareInterface>
    </joint>
    <actuator name="left_shoulder_lateral_joint_motor">
      <hardwareInterface>EffortJointInterface</hardwareInterface>
      <mechanicalReduction>1</mechanicalReduction>
    </actuator>
  </transmission>
  <transmission name="right_elbow_joint_tran">
    <type>transmission_interface/SimpleTransmission</type>
    <joint name="right_elbow_joint">
      <hardwareInterface>EffortJointInterface</hardwareInterface>
    </joint>
    <actuator name="right_elbow_joint_motor">
      <hardwareInterface>EffortJointInterface</hardwareInterface>
      <mechanicalReduction>1</mechanicalReduction>
    </actuator>
  </transmission>
  <transmission name="left_elbow_joint_tran">
    <type>transmission_interface/SimpleTransmission</type>
    <joint name="left_elbow_joint">
      <hardwareInterface>EffortJointInterface</hardwareInterface>
    </joint>
    <actuator name="left_elbow_joint_motor">
      <hardwareInterface>EffortJointInterface</hardwareInterface>
      <mechanicalReduction>1</mechanicalReduction>
    </actuator>
  </transmission>
  <xacro:hand_joint_gazebo prefix="right"/>
  <xacro:hand_joint_gazebo prefix="left"/>
  <transmission name="right_hip_twist_joint_tran">
    <type>transmission_interface/SimpleTransmission</type>
    <joint name="right_hip_twist_joint">
      <hardwareInterface>EffortJointInterface</hardwareInterface>
    </joint>
    <actuator name="right_hip_twist_joint_motor">
      <hardwareInterface>EffortJointInterface</hardwareInterface>
      <mechanicalReduction>1</mechanicalReduction>
    </actuator>
  </transmission>
  <transmission name="left_hip_twist_joint_tran">
    <type>transmission_interface/SimpleTransmission</type>
    <joint name="left_hip_twist_joint">
      <hardwareInterface>EffortJointInterface</hardwareInterface>
    </joint>
    <actuator name="left_hip_twist_joint_motor">
      <hardwareInterface>EffortJointInterface</hardwareInterface>
      <mechanicalReduction>1</mechanicalReduction>
    </actuator>
  </transmission>
  <transmission name="right_hip_lateral_joint_tran">
    <type>transmission_interface/SimpleTransmission</type>
    <joint name="right_hip_lateral_joint">
      <hardwareInterface>EffortJointInterface</hardwareInterface>
    </joint>
    <actuator name="right_hip_lateral_joint_motor">
      <hardwareInterface>EffortJointInterface</hardwareInterface>
      <mechanicalReduction>1</mechanicalReduction>
    </actuator>
  </transmission>
  <transmission name="left_hip_lateral_joint_tran">
    <type>transmission_interface/SimpleTransmission</type>
    <joint name="left_hip_lateral_joint">
      <hardwareInterface>EffortJointInterface</hardwareInterface>
    </joint>
    <actuator name="left_hip_lateral_joint_motor">
      <hardwareInterface>EffortJointInterface</hardwareInterface>
      <mechanicalReduction>1</mechanicalReduction>
    </actuator>
  </transmission>
  <transmission name="right_hip_swing_joint_tran">
    <type>transmission_interface/SimpleTransmission</type>
    <joint name="right_hip_swing_joint">
      <hardwareInterface>EffortJointInterface</hardwareInterface>
    </joint>
    <actuator name="right_hip_swing_joint_motor">
      <hardwareInterface>EffortJointInterface</hardwareInterface>
      <mechanicalReduction>1</mechanicalReduction>
    </actuator>
  </transmission>
  <transmission name="left_hip_swing_joint_tran">
    <type>transmission_interface/SimpleTransmission</type>
    <joint name="left_hip_swing_joint">
      <hardwareInterface>EffortJointInterface</hardwareInterface>
    </joint>
    <actuator name="left_hip_swing_joint_motor">
      <hardwareInterface>EffortJointInterface</hardwareInterface>
      <mechanicalReduction>1</mechanicalReduction>
    </actuator>
  </transmission>
  <transmission name="right_knee_joint_tran">
    <type>transmission_interface/SimpleTransmission</type>
    <joint name="right_knee_joint">
      <hardwareInterface>EffortJointInterface</hardwareInterface>
    </joint>
    <actuator name="right_knee_joint_motor">
      <hardwareInterface>EffortJointInterface</hardwareInterface>
      <mechanicalReduction>1</mechanicalReduction>
    </actuator>
  </transmission>
  <transmission name="left_knee_joint_tran">
    <type>transmission_interface/SimpleTransmission</type>
    <joint name="left_knee_joint">
      <hardwareInterface>EffortJointInterface</hardwareInterface>
    </joint>
    <actuator name="left_knee_joint_motor">
      <hardwareInterface>EffortJointInterface</hardwareInterface>
      <mechanicalReduction>1</mechanicalReduction>
    </actuator>
  </transmission>
  <transmission name="right_ankle_swing_joint_tran">
    <type>transmission_interface/SimpleTransmission</type>
    <joint name="right_ankle_swing_joint">
      <hardwareInterface>EffortJointInterface</hardwareInterface>
    </joint>
    <actuator name="right_ankle_swing_joint_motor">
      <hardwareInterface>EffortJointInterface</hardwareInterface>
      <mechanicalReduction>1</mechanicalReduction>
    </actuator>
  </transmission>
  <transmission name="left_ankle_swing_joint_tran">
    <type>transmission_interface/SimpleTransmission</type>
    <joint name="left_ankle_swing_joint">
      <hardwareInterface>EffortJointInterface</hardwareInterface>
    </joint>
    <actuator name="left_ankle_swing_joint_motor">
      <hardwareInterface>EffortJointInterface</hardwareInterface>
      <mechanicalReduction>1</mechanicalReduction>
    </actuator>
  </transmission>
  <transmission name="right_ankle_lateral_joint_tran">
    <type>transmission_interface/SimpleTransmission</type>
    <joint name="right_ankle_lateral_joint">
      <hardwareInterface>EffortJointInterface</hardwareInterface>
    </joint>
    <actuator name="right_ankle_lateral_joint_motor">
      <hardwareInterface>EffortJointInterface</hardwareInterface>
      <mechanicalReduction>1</mechanicalReduction>
    </actuator>
  </transmission>
  <transmission name="left_ankle_lateral_joint_tran">
    <type>transmission_interface/SimpleTransmission</type>
    <joint name="left_ankle_lateral_joint">
      <hardwareInterface>EffortJointInterface</hardwareInterface>
    </joint>
    <actuator name="left_ankle_lateral_joint_motor">
      <hardwareInterface>EffortJointInterface</hardwareInterface>
      <mechanicalReduction>1</mechanicalReduction>
    </actuator>
  </transmission>
  <xacro:foot_joint_gazebo prefix="right"/>
  <xacro:foot_joint_gazebo prefix="left"/>
  <!-- Typically, STL/DAE model units are in mm, but RViz units are in m, hence models must be scaled down by 1000. -->
  <!-- <xacro:macro name="shoulder_swing_joint" params="prefix reflect x"> -->
  <!-- Base -->
  <joint name="base_to_torso_joint" type="fixed">
    <parent link="base_link"/>
    <origin rpy="0 0 1.570795" xyz="0 0 0"/>
    <child link="torso_link"/>
  </joint>
  <link name="base_link">
    </link>
  <!-- Torso to right shoulder -->
  <joint name="right_shoulder_swing_joint" type="revolute">
    <parent link="torso_link"/>
    <!-- <origin xyz="${reflect*(-0.032)} 0 0" rpy="0 ${reflect*(-pi/2)} ${x*pi}"/> -->
    <origin rpy="-1.570795 0 1.570795" xyz="-0.032 0 0"/>
    <axis xyz="0 0 1"/>
    <child link="right_shoulder_swing_link"/>
    <limit effort="10" lower="-3.14159" upper="3.14159" velocity="1.0"/>
  </joint>
  <link name="right_shoulder_swing_link">
    <visual>
      <geometry>
        <mesh filename="file:///mnt/STORAGE/Dropbox/Personal/Programming/Bioloid/Linux/ROS/catkin_ws/src/bioloid_master/../../assets/cad/FP04-F1_FCD-Conv_BDR-Col.dae" scale="0.001 0.001 0.001"/>
      </geometry>
      <origin rpy="0 3.14159 -1.570795" xyz="-0.014 0 0.044"/>
    </visual>
    <collision name="right_shoulder_collision">
      <origin xyz="-0.006 0 0.0375"/>
      <geometry>
        <box size="0.039 0.052 0.036"/>
      </geometry>
    </collision>
    <inertial>
      <origin xyz="0 0 0"/>
      <mass value="1.0"/>
      <inertia ixx="0.001" ixy="0.0" ixz="0.0" iyy="0.001" iyz="0.0" izz="0.001"/>
    </inertial>
  </link>
  <!-- Torso to left shoulder -->
  <joint name="left_shoulder_swing_joint" type="revolute">
    <parent link="torso_link"/>
    <!-- <origin xyz="${reflect*(-0.032)} 0 0" rpy="0 ${reflect*(-pi/2)} ${x*pi}"/> -->
    <origin rpy="1.570795 0 -1.570795" xyz="0.032 0 0"/>
    <axis xyz="0 0 1"/>
    <child link="left_shoulder_swing_link"/>
    <limit effort="10" lower="-3.14159" upper="3.14159" velocity="1.0"/>
  </joint>
  <link name="left_shoulder_swing_link">
    <visual>
      <geometry>
        <mesh filename="file:///mnt/STORAGE/Dropbox/Personal/Programming/Bioloid/Linux/ROS/catkin_ws/src/bioloid_master/../../assets/cad/FP04-F1_FCD-Conv_BDR-Col.dae" scale="0.001 0.001 0.001"/>
      </geometry>
      <origin rpy="0 0 1.570795" xyz="0.014 0 -0.044"/>
    </visual>
    <collision name="left_shoulder_collision">
      <origin xyz="0.006 0 -0.0375"/>
      <geometry>
        <box size="0.039 0.052 0.036"/>
      </geometry>
    </collision>
    <inertial>
      <origin xyz="0 0 0"/>
      <mass value="1.0"/>
      <inertia ixx="0.001" ixy="0.0" ixz="0.0" iyy="0.001" iyz="0.0" izz="0.001"/>
    </inertial>
  </link>
  <!-- Right shoulder to upper arm -->
  <joint name="right_shoulder_lateral_joint" type="revolute">
    <parent link="right_shoulder_swing_link"/>
    <!-- <origin xyz="${reflect*(-0.014)} 0 ${reflect*0.044}" rpy="${-pi/2} 0 0"/> -->
    <origin rpy="-1.570795 1.570795 0" xyz="-0.014 0 0.044"/>
    <axis xyz="0 0 1"/>
    <child link="right_upper_arm_link"/>
    <limit effort="10" lower="-3.14159" upper="3.14159" velocity="1.0"/>
  </joint>
  <link name="right_upper_arm_link">
    <visual>
      <geometry>
        <mesh filename="file:///mnt/STORAGE/Dropbox/Personal/Programming/Bioloid/Linux/ROS/catkin_ws/src/bioloid_master/../../assets/cad/AX-12_FCD-Conv_BDR-Col.dae" scale="0.001 0.001 0.001"/>
      </geometry>
      <origin rpy="3.14159 0 1.570795" xyz="0 0 0"/>
    </visual>
    <visual>
      <geometry>
        <mesh filename="file:///mnt/STORAGE/Dropbox/Personal/Programming/Bioloid/Linux/ROS/catkin_ws/src/bioloid_master/../../assets/cad/BPF-BU_FCD-Conv_BDR-Col.dae" scale="0.001 0.001 0.001"/>
      </geometry>
      <origin rpy="1.570795 0 0" xyz="0 0 0.0185"/>
    </visual>
    <visual>
      <geometry>
        <mesh filename="file:///mnt/STORAGE/Dropbox/Personal/Programming/Bioloid/Linux/ROS/catkin_ws/src/bioloid_master/../../assets/cad/BPF-WA_FCD-Conv_BDR-Col.dae" scale="0.001 0.001 0.001"/>
      </geometry>
      <origin rpy="1.570795 0 0" xyz="0 0 0.019"/>
    </visual>
    <visual>
      <geometry>
        <mesh filename="file:///mnt/STORAGE/Dropbox/Personal/Programming/Bioloid/Linux/ROS/catkin_ws/src/bioloid_master/../../assets/cad/FP04-F3_FCD-Conv_BDR-Col.dae" scale="0.001 0.001 0.001"/>
      </geometry>
      <origin rpy="0 0 -1.570795" xyz="-0.0415 0 0"/>
    </visual>
    <visual>
      <geometry>
        <mesh filename="file:///mnt/STORAGE/Dropbox/Personal/Programming/Bioloid/Linux/ROS/catkin_ws/src/bioloid_master/../../assets/cad/FP04-F2_FCD-Conv_BDR-Col.dae" scale="0.001 0.001 0.001"/>
      </geometry>
      <origin rpy="0 1.570795 0" xyz="-0.0675 0 0"/>
    </visual>
    <collision name="right_upper arm_collision_proximal">
      <origin xyz="-0.0148 0 0"/>
      <geometry>
        <box size="0.054 0.033 0.044"/>
      </geometry>
    </collision>
    <collision name="right_upper arm_collision_distal">
      <origin xyz="-0.0555 0 0"/>
      <geometry>
        <box size="0.047 0.033 0.052"/>
      </geometry>
    </collision>
    <inertial>
      <origin xyz="0 0 0"/>
      <mass value="1.0"/>
      <inertia ixx="0.001" ixy="0.0" ixz="0.0" iyy="0.001" iyz="0.0" izz="0.001"/>
    </inertial>
  </link>
  <!-- Left shoulder to upper arm -->
  <joint name="left_shoulder_lateral_joint" type="revolute">
    <parent link="left_shoulder_swing_link"/>
    <!-- <origin xyz="${reflect*(-0.014)} 0 ${reflect*0.044}" rpy="${-pi/2} 0 0"/> -->
    <origin rpy="-1.570795 1.570795 0" xyz="0.014 0 -0.044"/>
    <axis xyz="0 0 1"/>
    <child link="left_upper_arm_link"/>
    <limit effort="10" lower="-3.14159" upper="3.14159" velocity="1.0"/>
  </joint>
  <link name="left_upper_arm_link">
    <visual>
      <geometry>
        <mesh filename="file:///mnt/STORAGE/Dropbox/Personal/Programming/Bioloid/Linux/ROS/catkin_ws/src/bioloid_master/../../assets/cad/AX-12_FCD-Conv_BDR-Col.dae" scale="0.001 0.001 0.001"/>
      </geometry>
      <origin rpy="0 0 1.570795" xyz="0 0 0"/>
    </visual>
    <visual>
      <geometry>
        <mesh filename="file:///mnt/STORAGE/Dropbox/Personal/Programming/Bioloid/Linux/ROS/catkin_ws/src/bioloid_master/../../assets/cad/BPF-BU_FCD-Conv_BDR-Col.dae" scale="0.001 0.001 0.001"/>
      </geometry>
      <origin rpy="-1.570795 0 0" xyz="0 0 -0.0185"/>
    </visual>
    <visual>
      <geometry>
        <mesh filename="file:///mnt/STORAGE/Dropbox/Personal/Programming/Bioloid/Linux/ROS/catkin_ws/src/bioloid_master/../../assets/cad/BPF-WA_FCD-Conv_BDR-Col.dae" scale="0.001 0.001 0.001"/>
      </geometry>
      <origin rpy="-1.570795 0 0" xyz="0 0 -0.019"/>
    </visual>
    <visual>
      <geometry>
        <mesh filename="file:///mnt/STORAGE/Dropbox/Personal/Programming/Bioloid/Linux/ROS/catkin_ws/src/bioloid_master/../../assets/cad/FP04-F3_FCD-Conv_BDR-Col.dae" scale="0.001 0.001 0.001"/>
      </geometry>
      <origin rpy="0 0 1.570795" xyz="0.0415 0 0"/>
    </visual>
    <visual>
      <geometry>
        <mesh filename="file:///mnt/STORAGE/Dropbox/Personal/Programming/Bioloid/Linux/ROS/catkin_ws/src/bioloid_master/../../assets/cad/FP04-F2_FCD-Conv_BDR-Col.dae" scale="0.001 0.001 0.001"/>
      </geometry>
      <origin rpy="0 -1.570795 0" xyz="0.0675 0 0"/>
    </visual>
    <collision name="left_upper arm_collision_proximal">
      <origin xyz="0.0148 0 0"/>
      <geometry>
        <box size="0.054 0.033 0.044"/>
      </geometry>
    </collision>
    <collision name="left_upper arm_collision_distal">
      <origin xyz="0.0555 0 0"/>
      <geometry>
        <box size="0.047 0.033 0.052"/>
      </geometry>
    </collision>
    <inertial>
      <origin xyz="0 0 0"/>
      <mass value="1.0"/>
      <inertia ixx="0.001" ixy="0.0" ixz="0.0" iyy="0.001" iyz="0.0" izz="0.001"/>
    </inertial>
  </link>
  <!-- Right upper arm to lower arm -->
  <joint name="right_elbow_joint" type="revolute">
    <parent link="right_upper_arm_link"/>
    <origin rpy="0 0 0" xyz="-0.0675 0 0"/>
    <axis xyz="0 0 1"/>
    <child link="right_lower_arm_link"/>
    <limit effort="10" lower="-1.77" upper="1.77" velocity="1.0"/>
  </joint>
  <link name="right_lower_arm_link">
    <!-- Motor 5 -->
    <visual>
      <geometry>
        <mesh filename="file:///mnt/STORAGE/Dropbox/Personal/Programming/Bioloid/Linux/ROS/catkin_ws/src/bioloid_master/../../assets/cad/AX-12_FCD-Conv_BDR-Col.dae" scale="0.001 0.001 0.001"/>
      </geometry>
      <origin rpy="3.14159 0 1.570795" xyz="0 0 0"/>
    </visual>
    <visual>
      <geometry>
        <mesh filename="file:///mnt/STORAGE/Dropbox/Personal/Programming/Bioloid/Linux/ROS/catkin_ws/src/bioloid_master/../../assets/cad/BPF-BU_FCD-Conv_BDR-Col.dae" scale="0.001 0.001 0.001"/>
      </geometry>
      <origin rpy="1.570795 0 0" xyz="0 0 0.0185"/>
    </visual>
    <visual>
      <geometry>
        <mesh filename="file:///mnt/STORAGE/Dropbox/Personal/Programming/Bioloid/Linux/ROS/catkin_ws/src/bioloid_master/../../assets/cad/BPF-WA_FCD-Conv_BDR-Col.dae" scale="0.001 0.001 0.001"/>
      </geometry>
      <origin rpy="1.570795 0 0" xyz="0 0 0.019"/>
    </visual>
    <visual>
      <geometry>
        <mesh filename="file:///mnt/STORAGE/Dropbox/Personal/Programming/Bioloid/Linux/ROS/catkin_ws/src/bioloid_master/../../assets/cad/FP04-F3_FCD-Conv_BDR-Col.dae" scale="0.001 0.001 0.001"/>
      </geometry>
      <origin rpy="0 0 -1.570795" xyz="-0.0415 0 0"/>
    </visual>
    <collision name="right_lower_arm_collision">
      <origin xyz="-0.0135 0 0"/>
      <geometry>
        <box size="0.051 0.033 0.044"/>
      </geometry>
    </collision>
    <inertial>
      <origin xyz="0 0 0"/>
      <mass value="1.0"/>
      <inertia ixx="0.001" ixy="0.0" ixz="0.0" iyy="0.001" iyz="0.0" izz="0.001"/>
    </inertial>
  </link>
  <!-- Left upper arm to lower arm -->
  <joint name="left_elbow_joint" type="revolute">
    <parent link="left_upper_arm_link"/>
    <origin rpy="0 0 0" xyz="0.0675 0 0"/>
    <axis xyz="0 0 1"/>
    <child link="left_lower_arm_link"/>
    <limit effort="10" lower="-1.77" upper="1.77" velocity="1.0"/>
  </joint>
  <link name="left_lower_arm_link">
    <!-- Motor 6 -->
    <visual>
      <geometry>
        <mesh filename="file:///mnt/STORAGE/Dropbox/Personal/Programming/Bioloid/Linux/ROS/catkin_ws/src/bioloid_master/../../assets/cad/AX-12_FCD-Conv_BDR-Col.dae" scale="0.001 0.001 0.001"/>
      </geometry>
      <origin rpy="0 0 1.570795" xyz="0 0 0"/>
    </visual>
    <visual>
      <geometry>
        <mesh filename="file:///mnt/STORAGE/Dropbox/Personal/Programming/Bioloid/Linux/ROS/catkin_ws/src/bioloid_master/../../assets/cad/BPF-BU_FCD-Conv_BDR-Col.dae" scale="0.001 0.001 0.001"/>
      </geometry>
      <origin rpy="-1.570795 0 0" xyz="0 0 -0.0185"/>
    </visual>
    <visual>
      <geometry>
        <mesh filename="file:///mnt/STORAGE/Dropbox/Personal/Programming/Bioloid/Linux/ROS/catkin_ws/src/bioloid_master/../../assets/cad/BPF-WA_FCD-Conv_BDR-Col.dae" scale="0.001 0.001 0.001"/>
      </geometry>
      <origin rpy="-1.570795 0 0" xyz="0 0 -0.019"/>
    </visual>
    <visual>
      <geometry>
        <mesh filename="file:///mnt/STORAGE/Dropbox/Personal/Programming/Bioloid/Linux/ROS/catkin_ws/src/bioloid_master/../../assets/cad/FP04-F3_FCD-Conv_BDR-Col.dae" scale="0.001 0.001 0.001"/>
      </geometry>
      <origin rpy="0 0 1.570795" xyz="0.0415 0 0"/>
    </visual>
    <collision name="left_lower_arm_collision">
      <origin xyz="0.017 0 0"/>
      <geometry>
        <box size="0.058 0.033 0.044"/>
      </geometry>
    </collision>
    <inertial>
      <origin xyz="0 0 0"/>
      <mass value="1.0"/>
      <inertia ixx="0.001" ixy="0.0" ixz="0.0" iyy="0.001" iyz="0.0" izz="0.001"/>
    </inertial>
  </link>
  <!-- Right lower arm to hand -->
  <joint name="right_hand_joint" type="fixed">
    <parent link="right_lower_arm_link"/>
    <origin rpy="0 0 0" xyz="0 0 0"/>
    <child link="right_hand_link"/>
  </joint>
  <link name="right_hand_link">
    <visual>
      <geometry>
        <mesh filename="file:///mnt/STORAGE/Dropbox/Personal/Programming/Bioloid/Linux/ROS/catkin_ws/src/bioloid_master/../../assets/cad/FP04-F11_FCD-Conv_BDR-Col.dae" scale="0.001 0.001 0.001"/>
      </geometry>
      <origin rpy="-3.14159 1.570795 0" xyz="-0.0415 0 0"/>
    </visual>
    <collision name="right_palm_collision">
      <origin xyz="-0.039 0 0"/>
      <geometry>
        <box size="0.0131 0.0265 0.044"/>
      </geometry>
    </collision>
    <collision name="right_fingers_collision">
      <origin xyz="-0.0701 -0.0077 0"/>
      <geometry>
        <box size="0.0575 0.0175 0.035"/>
      </geometry>
    </collision>
    <inertial>
      <origin xyz="0 0 0"/>
      <mass value="1.0"/>
      <inertia ixx="0.001" ixy="0.0" ixz="0.0" iyy="0.001" iyz="0.0" izz="0.001"/>
    </inertial>
  </link>
  <!-- Left lower arm to hand -->
  <joint name="left_hand_joint" type="fixed">
    <parent link="left_lower_arm_link"/>
    <origin rpy="0 0 0" xyz="0 0 0"/>
    <child link="left_hand_link"/>
  </joint>
  <link name="left_hand_link">
    <visual>
      <geometry>
        <mesh filename="file:///mnt/STORAGE/Dropbox/Personal/Programming/Bioloid/Linux/ROS/catkin_ws/src/bioloid_master/../../assets/cad/FP04-F11_FCD-Conv_BDR-Col.dae" scale="0.001 0.001 0.001"/>
      </geometry>
      <origin rpy="0 1.570795 0" xyz="0.0415 0 0"/>
    </visual>
    <collision name="left_palm_collision">
      <origin xyz="0.039 0 0"/>
      <geometry>
        <box size="0.0131 0.0265 0.044"/>
      </geometry>
    </collision>
    <collision name="left_fingers_collision">
      <origin xyz="0.0701 0.0077 0"/>
      <geometry>
        <box size="0.0575 0.0175 0.035"/>
      </geometry>
    </collision>
    <inertial>
      <origin xyz="0 0 0"/>
      <mass value="1.0"/>
      <inertia ixx="0.001" ixy="0.0" ixz="0.0" iyy="0.001" iyz="0.0" izz="0.001"/>
    </inertial>
  </link>
  <!-- Torso to right hip twist -->
  <joint name="right_hip_twist_joint" type="revolute">
    <parent link="torso_link"/>
    <origin rpy="3.14159 0 0.0" xyz="-0.033 0.016 -0.0655"/>
    <axis xyz="0 0 1"/>
    <child link="right_hip_twist_link"/>
    <limit effort="10" lower="-0.7853975" upper="0.7853975" velocity="1.0"/>
  </joint>
  <link name="right_hip_twist_link">
    <visual>
      <geometry>
        <mesh filename="file:///mnt/STORAGE/Dropbox/Personal/Programming/Bioloid/Linux/ROS/catkin_ws/src/bioloid_master/../../assets/cad/FP04-F5_FCD-Conv_BDR-Col.dae" scale="0.001 0.001 0.001"/>
      </geometry>
      <origin rpy="3.14159 0 0" xyz="0 0 0.05"/>
    </visual>
    <collision name="right_hip_twist_collision">
      <origin xyz="0 0.0008 0.041"/>
      <geometry>
        <box size="0.029 0.083 0.0405"/>
      </geometry>
    </collision>
    <inertial>
      <origin xyz="0 0 0"/>
      <mass value="1.0"/>
      <inertia ixx="0.001" ixy="0.0" ixz="0.0" iyy="0.001" iyz="0.0" izz="0.001"/>
    </inertial>
  </link>
  <!-- Torso to left hip twist -->
  <joint name="left_hip_twist_joint" type="revolute">
    <parent link="torso_link"/>
    <origin rpy="0.0 0 3.14159" xyz="0.033 0.016 -0.0655"/>
    <axis xyz="0 0 1"/>
    <child link="left_hip_twist_link"/>
    <limit effort="10" lower="-0.7853975" upper="0.7853975" velocity="1.0"/>
  </joint>
  <link name="left_hip_twist_link">
    <visual>
      <geometry>
        <mesh filename="file:///mnt/STORAGE/Dropbox/Personal/Programming/Bioloid/Linux/ROS/catkin_ws/src/bioloid_master/../../assets/cad/FP04-F5_FCD-Conv_BDR-Col.dae" scale="0.001 0.001 0.001"/>
      </geometry>
      <origin rpy="0 0 3.14159" xyz="0 0 -0.05"/>
    </visual>
    <collision name="left_hip_twist_collision">
      <origin xyz="0 0.0008 -0.041"/>
      <geometry>
        <box size="0.029 0.083 0.0405"/>
      </geometry>
    </collision>
    <inertial>
      <origin xyz="0 0 0"/>
      <mass value="1.0"/>
      <inertia ixx="0.001" ixy="0.0" ixz="0.0" iyy="0.001" iyz="0.0" izz="0.001"/>
    </inertial>
  </link>
  <!-- Right hip twist to hip lateral -->
  <joint name="right_hip_lateral_joint" type="revolute">
    <parent link="right_hip_twist_link"/>
    <origin rpy="1.570795 0 0" xyz="0 -0.0153 0.05"/>
    <axis xyz="0 0 1"/>
    <child link="right_hip_lateral_link"/>
    <limit effort="10" lower="-0.3" upper="1.0" velocity="1.0"/>
  </joint>
  <link name="right_hip_lateral_link">
    <!-- Motor 9 -->
    <visual>
      <geometry>
        <mesh filename="file:///mnt/STORAGE/Dropbox/Personal/Programming/Bioloid/Linux/ROS/catkin_ws/src/bioloid_master/../../assets/cad/AX-12_FCD-Conv_BDR-Col.dae" scale="0.001 0.001 0.001"/>
      </geometry>
      <origin rpy="0 0 3.14159" xyz="0 0 0"/>
    </visual>
    <visual>
      <geometry>
        <mesh filename="file:///mnt/STORAGE/Dropbox/Personal/Programming/Bioloid/Linux/ROS/catkin_ws/src/bioloid_master/../../assets/cad/FP04-F6_FCD-Conv_BDR-Col.dae" scale="0.001 0.001 0.001"/>
      </geometry>
      <origin rpy="0 -1.570795 -1.570795" xyz="-0.019 0.0145 0.016"/>
    </visual>
    <visual>
      <geometry>
        <mesh filename="file:///mnt/STORAGE/Dropbox/Personal/Programming/Bioloid/Linux/ROS/catkin_ws/src/bioloid_master/../../assets/cad/FP04-F6_FCD-Conv_BDR-Col.dae" scale="0.001 0.001 0.001"/>
      </geometry>
      <origin rpy="0 -1.570795 1.570795" xyz="0.019 0.0145 0.016"/>
    </visual>
    <!-- Motor 11 -->
    <visual>
      <geometry>
        <mesh filename="file:///mnt/STORAGE/Dropbox/Personal/Programming/Bioloid/Linux/ROS/catkin_ws/src/bioloid_master/../../assets/cad/AX-12_FCD-Conv_BDR-Col.dae" scale="0.001 0.001 0.001"/>
      </geometry>
      <origin rpy="3.14159 -1.570795 0" xyz="0 0 -0.032"/>
    </visual>
    <visual>
      <geometry>
        <mesh filename="file:///mnt/STORAGE/Dropbox/Personal/Programming/Bioloid/Linux/ROS/catkin_ws/src/bioloid_master/../../assets/cad/BPF-BU_FCD-Conv_BDR-Col.dae" scale="0.001 0.001 0.001"/>
      </geometry>
      <origin rpy="-1.570795 0 0" xyz="0 0 -0.05"/>
    </visual>
    <visual>
      <geometry>
        <mesh filename="file:///mnt/STORAGE/Dropbox/Personal/Programming/Bioloid/Linux/ROS/catkin_ws/src/bioloid_master/../../assets/cad/FP04-F7_FCD-Conv_BDR-Col.dae" scale="0.001 0.001 0.001"/>
      </geometry>
      <origin rpy="1.570795 0 -1.570795" xyz="0 0.0145 -0.051"/>
    </visual>
    <collision name="right_hip_lateral_collision">
      <origin xyz="0 0.0135 -0.0153"/>
      <geometry>
        <box size="0.04 0.051 0.0721"/>
      </geometry>
    </collision>
    <inertial>
      <origin xyz="0 0 0"/>
      <mass value="1.0"/>
      <inertia ixx="0.001" ixy="0.0" ixz="0.0" iyy="0.001" iyz="0.0" izz="0.001"/>
    </inertial>
  </link>
  <!-- Left hip twist to hip lateral -->
  <joint name="left_hip_lateral_joint" type="revolute">
    <parent link="left_hip_twist_link"/>
    <origin rpy="-1.570795 0 0" xyz="0 -0.0153 -0.05"/>
    <axis xyz="0 0 1"/>
    <child link="left_hip_lateral_link"/>
    <limit effort="10" lower="-0.3" upper="1.0" velocity="1.0"/>
  </joint>
  <link name="left_hip_lateral_link">
    <!-- Motor 10 -->
    <visual>
      <geometry>
        <mesh filename="file:///mnt/STORAGE/Dropbox/Personal/Programming/Bioloid/Linux/ROS/catkin_ws/src/bioloid_master/../../assets/cad/AX-12_FCD-Conv_BDR-Col.dae" scale="0.001 0.001 0.001"/>
      </geometry>
      <origin rpy="3.14159 0 0" xyz="0 0 0"/>
    </visual>
    <visual>
      <geometry>
        <mesh filename="file:///mnt/STORAGE/Dropbox/Personal/Programming/Bioloid/Linux/ROS/catkin_ws/src/bioloid_master/../../assets/cad/FP04-F6_FCD-Conv_BDR-Col.dae" scale="0.001 0.001 0.001"/>
      </geometry>
      <origin rpy="0 1.570795 -1.570795" xyz="-0.019 0.0145 -0.016"/>
    </visual>
    <visual>
      <geometry>
        <mesh filename="file:///mnt/STORAGE/Dropbox/Personal/Programming/Bioloid/Linux/ROS/catkin_ws/src/bioloid_master/../../assets/cad/FP04-F6_FCD-Conv_BDR-Col.dae" scale="0.001 0.001 0.001"/>
      </geometry>
      <origin rpy="0 1.570795 1.570795" xyz="0.019 0.0145 -0.016"/>
    </visual>
    <!-- Motor 12 -->
    <visual>
      <geometry>
        <mesh filename="file:///mnt/STORAGE/Dropbox/Personal/Programming/Bioloid/Linux/ROS/catkin_ws/src/bioloid_master/../../assets/cad/AX-12_FCD-Conv_BDR-Col.dae" scale="0.001 0.001 0.001"/>
      </geometry>
      <origin rpy="3.14159 -1.570795 0" xyz="0 0 0.032"/>
    </visual>
    <visual>
      <geometry>
        <mesh filename="file:///mnt/STORAGE/Dropbox/Personal/Programming/Bioloid/Linux/ROS/catkin_ws/src/bioloid_master/../../assets/cad/BPF-BU_FCD-Conv_BDR-Col.dae" scale="0.001 0.001 0.001"/>
      </geometry>
      <origin rpy="1.570795 0 0" xyz="0 0 0.05"/>
    </visual>
    <visual>
      <geometry>
        <mesh filename="file:///mnt/STORAGE/Dropbox/Personal/Programming/Bioloid/Linux/ROS/catkin_ws/src/bioloid_master/../../assets/cad/FP04-F7_FCD-Conv_BDR-Col.dae" scale="0.001 0.001 0.001"/>
      </geometry>
      <origin rpy="-1.570795 0 -1.570795" xyz="0 0.0145 0.051"/>
    </visual>
    <collision name="left_hip_lateral_collision">
      <origin xyz="0 0.0135 0.0153"/>
      <geometry>
        <box size="0.04 0.051 0.0721"/>
      </geometry>
    </collision>
    <inertial>
      <origin xyz="0 0 0"/>
      <mass value="1.0"/>
      <inertia ixx="0.001" ixy="0.0" ixz="0.0" iyy="0.001" iyz="0.0" izz="0.001"/>
    </inertial>
  </link>
  <!-- Right hip lateral to upper leg -->
  <joint name="right_hip_swing_joint" type="revolute">
    <parent link="right_hip_lateral_link"/>
    <origin rpy="0.0 -1.570795 0" xyz="0 0 -0.032"/>
    <axis xyz="0 0 1"/>
    <child link="right_upper_leg_link"/>
    <limit effort="10" lower="-1.570795" upper="1.9" velocity="1.0"/>
  </joint>
  <link name="right_upper_leg_link">
    <visual>
      <geometry>
        <mesh filename="file:///mnt/STORAGE/Dropbox/Personal/Programming/Bioloid/Linux/ROS/catkin_ws/src/bioloid_master/../../assets/cad/FP04-F4_FCD-Conv_BDR-Col.dae" scale="0.001 0.001 0.001"/>
      </geometry>
      <origin rpy="-1.570795 1.570795 0" xyz="0 0 0"/>
    </visual>
    <visual>
      <geometry>
        <mesh filename="file:///mnt/STORAGE/Dropbox/Personal/Programming/Bioloid/Linux/ROS/catkin_ws/src/bioloid_master/../../assets/cad/FP04-F1_FCD-Conv_BDR-Col.dae" scale="0.001 0.001 0.001"/>
      </geometry>
      <origin rpy="1.570795 -1.570795 0" xyz="0.0145 0.075 0"/>
    </visual>
    <collision name="right_upper_leg_proximal_collision">
      <origin xyz="0 0.0214 0"/>
      <geometry>
        <box size="0.03 0.065 0.049"/>
      </geometry>
    </collision>
    <collision name="right_upper_leg_distal_collision">
      <origin xyz="0.0065 0.0675 0"/>
      <geometry>
        <box size="0.04 0.0371 0.049"/>
      </geometry>
    </collision>
    <inertial>
      <origin xyz="0 0 0"/>
      <mass value="1.0"/>
      <inertia ixx="0.001" ixy="0.0" ixz="0.0" iyy="0.001" iyz="0.0" izz="0.001"/>
    </inertial>
  </link>
  <!-- Left hip lateral to upper leg -->
  <joint name="left_hip_swing_joint" type="revolute">
    <parent link="left_hip_lateral_link"/>
    <origin rpy="3.14159 -1.570795 0" xyz="0 0 0.032"/>
    <axis xyz="0 0 1"/>
    <child link="left_upper_leg_link"/>
    <limit effort="10" lower="-1.570795" upper="1.9" velocity="1.0"/>
  </joint>
  <link name="left_upper_leg_link">
    <visual>
      <geometry>
        <mesh filename="file:///mnt/STORAGE/Dropbox/Personal/Programming/Bioloid/Linux/ROS/catkin_ws/src/bioloid_master/../../assets/cad/FP04-F4_FCD-Conv_BDR-Col.dae" scale="0.001 0.001 0.001"/>
      </geometry>
      <origin rpy="1.570795 1.570795 0" xyz="0 0 0"/>
    </visual>
    <visual>
      <geometry>
        <mesh filename="file:///mnt/STORAGE/Dropbox/Personal/Programming/Bioloid/Linux/ROS/catkin_ws/src/bioloid_master/../../assets/cad/FP04-F1_FCD-Conv_BDR-Col.dae" scale="0.001 0.001 0.001"/>
      </geometry>
      <origin rpy="-1.570795 -1.570795 0" xyz="-0.0145 -0.075 0"/>
    </visual>
    <collision name="left_upper_leg_proximal_collision">
      <origin xyz="0 -0.0214 0"/>
      <geometry>
        <box size="0.03 0.065 0.049"/>
      </geometry>
    </collision>
    <collision name="left_upper_leg_distal_collision">
      <origin xyz="-0.0065 -0.0675 0"/>
      <geometry>
        <box size="0.04 0.0371 0.049"/>
      </geometry>
    </collision>
    <inertial>
      <origin xyz="0 0 0"/>
      <mass value="1.0"/>
      <inertia ixx="0.001" ixy="0.0" ixz="0.0" iyy="0.001" iyz="0.0" izz="0.001"/>
    </inertial>
  </link>
  <!-- Right upper leg to lower leg -->
  <joint name="right_knee_joint" type="revolute">
    <parent link="right_upper_leg_link"/>
    <origin rpy="0 0 0" xyz="0.0145 0.075 0"/>
    <axis xyz="0 0 1"/>
    <child link="right_lower_leg_link"/>
    <limit effort="10" lower="-3.14159" upper="0.0" velocity="1.0"/>
  </joint>
  <link name="right_lower_leg_link">
    <!-- Motor 13 -->
    <visual>
      <geometry>
        <mesh filename="file:///mnt/STORAGE/Dropbox/Personal/Programming/Bioloid/Linux/ROS/catkin_ws/src/bioloid_master/../../assets/cad/AX-12_FCD-Conv_BDR-Col.dae" scale="0.001 0.001 0.001"/>
      </geometry>
      <origin rpy="0 3.14159 -1.570795" xyz="0 0 0"/>
    </visual>
    <visual>
      <geometry>
        <mesh filename="file:///mnt/STORAGE/Dropbox/Personal/Programming/Bioloid/Linux/ROS/catkin_ws/src/bioloid_master/../../assets/cad/FP04-F3_FCD-Conv_BDR-Col.dae" scale="0.001 0.001 0.001"/>
      </geometry>
      <origin rpy="0 0 3.14159" xyz="-0.0145 0.019 0"/>
    </visual>
    <visual>
      <geometry>
        <mesh filename="file:///mnt/STORAGE/Dropbox/Personal/Programming/Bioloid/Linux/ROS/catkin_ws/src/bioloid_master/../../assets/cad/FP04-F4_FCD-Conv_BDR-Col.dae" scale="0.001 0.001 0.001"/>
      </geometry>
      <origin rpy="1.570795 -1.570795 0" xyz="-0.0145 0.071 0"/>
    </visual>
    <collision name="right_lower_leg_proximal_collision">
      <origin xyz="-0.0135 0 0"/>
      <geometry>
        <box size="0.051 0.033 0.044"/>
      </geometry>
    </collision>
    <collision name="right_lower_leg_distal_collision">
      <origin xyz="-0.0145 0.0492 0"/>
      <geometry>
        <box size="0.03 0.067 0.049"/>
      </geometry>
    </collision>
    <inertial>
      <origin xyz="0 0 0"/>
      <mass value="1.0"/>
      <inertia ixx="0.001" ixy="0.0" ixz="0.0" iyy="0.001" iyz="0.0" izz="0.001"/>
    </inertial>
  </link>
  <!-- Left upper leg to lower leg -->
  <joint name="left_knee_joint" type="revolute">
    <parent link="left_upper_leg_link"/>
    <origin rpy="0 0 0" xyz="-0.0145 -0.075 0"/>
    <axis xyz="0 0 1"/>
    <child link="left_lower_leg_link"/>
    <limit effort="10" lower="-3.14159" upper="0.0" velocity="1.0"/>
  </joint>
  <link name="left_lower_leg_link">
    <!-- Motor 14 -->
    <visual>
      <geometry>
        <mesh filename="file:///mnt/STORAGE/Dropbox/Personal/Programming/Bioloid/Linux/ROS/catkin_ws/src/bioloid_master/../../assets/cad/AX-12_FCD-Conv_BDR-Col.dae" scale="0.001 0.001 0.001"/>
      </geometry>
      <origin rpy="0 0 1.570795" xyz="0 0 0"/>
    </visual>
    <visual>
      <geometry>
        <mesh filename="file:///mnt/STORAGE/Dropbox/Personal/Programming/Bioloid/Linux/ROS/catkin_ws/src/bioloid_master/../../assets/cad/FP04-F3_FCD-Conv_BDR-Col.dae" scale="0.001 0.001 0.001"/>
      </geometry>
      <origin rpy="0 0 0" xyz="0.0145 -0.019 0"/>
    </visual>
    <visual>
      <geometry>
        <mesh filename="file:///mnt/STORAGE/Dropbox/Personal/Programming/Bioloid/Linux/ROS/catkin_ws/src/bioloid_master/../../assets/cad/FP04-F4_FCD-Conv_BDR-Col.dae" scale="0.001 0.001 0.001"/>
      </geometry>
      <origin rpy="-1.570795 -1.570795 0" xyz="0.0145 -0.071 0"/>
    </visual>
    <collision name="left_lower_leg_proximal_collision">
      <origin xyz="0.0135 0 0"/>
      <geometry>
        <box size="0.051 0.033 0.044"/>
      </geometry>
    </collision>
    <collision name="left_lower_leg_distal_collision">
      <origin xyz="0.0145 -0.0492 0"/>
      <geometry>
        <box size="0.03 0.067 0.049"/>
      </geometry>
    </collision>
    <inertial>
      <origin xyz="0 0 0"/>
      <mass value="1.0"/>
      <inertia ixx="0.001" ixy="0.0" ixz="0.0" iyy="0.001" iyz="0.0" izz="0.001"/>
    </inertial>
  </link>
  <!-- Right lower leg to ankle swing -->
  <joint name="right_ankle_swing_joint" type="revolute">
    <parent link="right_lower_leg_link"/>
    <origin rpy="0 0 0" xyz="-0.0145 0.071 0"/>
    <axis xyz="0 0 1"/>
    <child link="right_ankle_swing_link"/>
    <limit effort="10" lower="-0.45" upper="1.570795" velocity="1.0"/>
  </joint>
  <link name="right_ankle_swing_link">
    <!-- Motor 15 -->
    <visual>
      <geometry>
        <mesh filename="file:///mnt/STORAGE/Dropbox/Personal/Programming/Bioloid/Linux/ROS/catkin_ws/src/bioloid_master/../../assets/cad/AX-12_FCD-Conv_BDR-Col.dae" scale="0.001 0.001 0.001"/>
      </geometry>
      <origin rpy="0 3.14159 0" xyz="0 0 0"/>
    </visual>
    <visual>
      <geometry>
        <mesh filename="file:///mnt/STORAGE/Dropbox/Personal/Programming/Bioloid/Linux/ROS/catkin_ws/src/bioloid_master/../../assets/cad/FP04-F7_FCD-Conv_BDR-Col.dae" scale="0.001 0.001 0.001"/>
      </geometry>
      <origin rpy="3.14159 0 1.570795" xyz="-0.019 -0.0145 0"/>
    </visual>
    <!-- Motor 17 -->
    <visual>
      <geometry>
        <mesh filename="file:///mnt/STORAGE/Dropbox/Personal/Programming/Bioloid/Linux/ROS/catkin_ws/src/bioloid_master/../../assets/cad/AX-12_FCD-Conv_BDR-Col.dae" scale="0.001 0.001 0.001"/>
      </geometry>
      <origin rpy="0 1.570795 0" xyz="0.032 0 0"/>
    </visual>
    <visual>
      <geometry>
        <mesh filename="file:///mnt/STORAGE/Dropbox/Personal/Programming/Bioloid/Linux/ROS/catkin_ws/src/bioloid_master/../../assets/cad/FP04-F6_FCD-Conv_BDR-Col.dae" scale="0.001 0.001 0.001"/>
      </geometry>
      <origin rpy="-1.570795 0 0" xyz="0.048 -0.0145 0.019"/>
    </visual>
    <visual>
      <geometry>
        <mesh filename="file:///mnt/STORAGE/Dropbox/Personal/Programming/Bioloid/Linux/ROS/catkin_ws/src/bioloid_master/../../assets/cad/FP04-F6_FCD-Conv_BDR-Col.dae" scale="0.001 0.001 0.001"/>
      </geometry>
      <origin rpy="1.570795 0 0" xyz="0.048 -0.0145 -0.019"/>
    </visual>
    <collision name="right_ankle_swing_collision">
      <origin xyz="0.0167 -0.0135 0"/>
      <geometry>
        <box size="0.0721 0.051 0.04"/>
      </geometry>
    </collision>
    <inertial>
      <origin xyz="0 0 0"/>
      <mass value="1.0"/>
      <inertia ixx="0.001" ixy="0.0" ixz="0.0" iyy="0.001" iyz="0.0" izz="0.001"/>
    </inertial>
  </link>
  <!-- Left lower leg to ankle swing -->
  <joint name="left_ankle_swing_joint" type="revolute">
    <parent link="left_lower_leg_link"/>
    <origin rpy="0 0 0" xyz="0.0145 -0.071 0"/>
    <axis xyz="0 0 1"/>
    <child link="left_ankle_swing_link"/>
    <limit effort="10" lower="-0.45" upper="1.570795" velocity="1.0"/>
  </joint>
  <link name="left_ankle_swing_link">
    <!-- Motor 16 -->
    <visual>
      <geometry>
        <mesh filename="file:///mnt/STORAGE/Dropbox/Personal/Programming/Bioloid/Linux/ROS/catkin_ws/src/bioloid_master/../../assets/cad/AX-12_FCD-Conv_BDR-Col.dae" scale="0.001 0.001 0.001"/>
      </geometry>
      <origin rpy="0 0 3.14159" xyz="0 0 0"/>
    </visual>
    <visual>
      <geometry>
        <mesh filename="file:///mnt/STORAGE/Dropbox/Personal/Programming/Bioloid/Linux/ROS/catkin_ws/src/bioloid_master/../../assets/cad/FP04-F7_FCD-Conv_BDR-Col.dae" scale="0.001 0.001 0.001"/>
      </geometry>
      <origin rpy="3.14159 0 -1.570795" xyz="0.019 0.0145 0"/>
    </visual>
    <!-- Motor 18 -->
    <visual>
      <geometry>
        <mesh filename="file:///mnt/STORAGE/Dropbox/Personal/Programming/Bioloid/Linux/ROS/catkin_ws/src/bioloid_master/../../assets/cad/AX-12_FCD-Conv_BDR-Col.dae" scale="0.001 0.001 0.001"/>
      </geometry>
      <origin rpy="3.14159 1.570795 0" xyz="-0.032 0 0"/>
    </visual>
    <visual>
      <geometry>
        <mesh filename="file:///mnt/STORAGE/Dropbox/Personal/Programming/Bioloid/Linux/ROS/catkin_ws/src/bioloid_master/../../assets/cad/FP04-F6_FCD-Conv_BDR-Col.dae" scale="0.001 0.001 0.001"/>
      </geometry>
      <origin rpy="1.570795 0 3.14159" xyz="-0.048 0.0145 -0.019"/>
    </visual>
    <visual>
      <geometry>
        <mesh filename="file:///mnt/STORAGE/Dropbox/Personal/Programming/Bioloid/Linux/ROS/catkin_ws/src/bioloid_master/../../assets/cad/FP04-F6_FCD-Conv_BDR-Col.dae" scale="0.001 0.001 0.001"/>
      </geometry>
      <origin rpy="-1.570795 0 3.14159" xyz="-0.048 0.0145 0.019"/>
    </visual>
    <collision name="left_ankle_swing_collision">
      <origin xyz="-0.0167 0.0135 0"/>
      <geometry>
        <box size="0.0721 0.051 0.04"/>
      </geometry>
    </collision>
    <inertial>
      <origin xyz="0 0 0"/>
      <mass value="1.0"/>
      <inertia ixx="0.001" ixy="0.0" ixz="0.0" iyy="0.001" iyz="0.0" izz="0.001"/>
    </inertial>
  </link>
  <!-- Right ankle swing to ankle lateral -->
  <joint name="right_ankle_lateral_joint" type="revolute">
    <parent link="right_ankle_swing_link"/>
    <origin rpy="0 1.570795 0" xyz="0.032 0 0"/>
    <axis xyz="0 0 1"/>
    <child link="right_ankle_lateral_link"/>
    <limit effort="10" lower="-0.7" upper="0.7" velocity="1.0"/>
  </joint>
  <link name="right_ankle_lateral_link">
    <visual>
      <geometry>
        <mesh filename="file:///mnt/STORAGE/Dropbox/Personal/Programming/Bioloid/Linux/ROS/catkin_ws/src/bioloid_master/../../assets/cad/BPF-BU_FCD-Conv_BDR-Col.dae" scale="0.001 0.001 0.001"/>
      </geometry>
      <origin rpy="-1.570795 0 0" xyz="0 0 -0.05"/>
    </visual>
    <visual>
      <geometry>
        <mesh filename="file:///mnt/STORAGE/Dropbox/Personal/Programming/Bioloid/Linux/ROS/catkin_ws/src/bioloid_master/../../assets/cad/FP04-F5_FCD-Conv_BDR-Col.dae" scale="0.001 0.001 0.001"/>
      </geometry>
      <origin rpy="-1.570795 3.14159 0" xyz="0 0 -0.0153"/>
    </visual>
    <collision name="right_ankle_lateral_collision">
      <origin xyz="0 0.009 -0.016"/>
      <geometry>
        <box size="0.029 0.0405 0.083"/>
      </geometry>
    </collision>
    <inertial>
      <origin xyz="0 0 0"/>
      <mass value="1.0"/>
      <inertia ixx="0.001" ixy="0.0" ixz="0.0" iyy="0.001" iyz="0.0" izz="0.001"/>
    </inertial>
  </link>
  <!-- Left ankle swing to ankle lateral -->
  <joint name="left_ankle_lateral_joint" type="revolute">
    <parent link="left_ankle_swing_link"/>
    <origin rpy="0 1.570795 0" xyz="-0.032 0 0"/>
    <axis xyz="0 0 1"/>
    <child link="left_ankle_lateral_link"/>
    <limit effort="10" lower="-0.7" upper="0.7" velocity="1.0"/>
  </joint>
  <link name="left_ankle_lateral_link">
    <visual>
      <geometry>
        <mesh filename="file:///mnt/STORAGE/Dropbox/Personal/Programming/Bioloid/Linux/ROS/catkin_ws/src/bioloid_master/../../assets/cad/BPF-BU_FCD-Conv_BDR-Col.dae" scale="0.001 0.001 0.001"/>
      </geometry>
      <origin rpy="1.570795 0 0" xyz="0 0 0.05"/>
    </visual>
    <visual>
      <geometry>
        <mesh filename="file:///mnt/STORAGE/Dropbox/Personal/Programming/Bioloid/Linux/ROS/catkin_ws/src/bioloid_master/../../assets/cad/FP04-F5_FCD-Conv_BDR-Col.dae" scale="0.001 0.001 0.001"/>
      </geometry>
      <origin rpy="1.570795 3.14159 0" xyz="0 0 0.0153"/>
    </visual>
    <collision name="left_ankle_lateral_collision">
      <origin xyz="0 -0.009 0.016"/>
      <geometry>
        <box size="0.029 0.0405 0.083"/>
      </geometry>
    </collision>
    <inertial>
      <origin xyz="0 0 0"/>
      <mass value="1.0"/>
      <inertia ixx="0.001" ixy="0.0" ixz="0.0" iyy="0.001" iyz="0.0" izz="0.001"/>
    </inertial>
  </link>
  <!-- Right ankle lateral to foot -->
  <joint name="right_foot_joint" type="fixed">
    <parent link="right_ankle_lateral_link"/>
    <origin rpy="0 0 0" xyz="0 0 0"/>
    <child link="right_foot_link"/>
  </joint>
  <!-- Left ankle lateral to foot -->
  <joint name="left_foot_joint" type="fixed">
    <parent link="left_ankle_lateral_link"/>
    <origin rpy="0 0 0" xyz="0 0 0"/>
    <child link="left_foot_link"/>
  </joint>
</robot>
