<?xml version="1.0" ?>
<!-- =================================================================================== -->
<!-- |    This document was autogenerated by xacro from /mnt/STORAGE/Dropbox/Personal/Programming/Bioloid/Linux/ROS/catkin_ws/src/bioloid_master/urdf/bioloid.xacro | -->
<!-- |    EDITING THIS FILE BY HAND IS NOT RECOMMENDED                                 | -->
<!-- =================================================================================== -->
<robot name="bioloid" xmlns:xacro="http://www.ros.org/wiki/xacro">
  <!-- IMU -->
  <joint name="imu_to_base_joint" type="fixed">
    <parent link="imu_link"/>
    <origin rpy="0 0 0" xyz="0.01 0 0.054"/>
    <child link="base_link"/>
  </joint>
  <link name="imu_link">
    <visual>
      <geometry>
        <box size="0.04 0.02 0.005"/>
      </geometry>
      <material name="green">
        <color rgba="0.0 1.0 0.0 1.0"/>
      </material>
    </visual>
    <inertial>
      <origin xyz="0 0 0"/>
      <mass value="1.0"/>
      <inertia ixx="0.001" ixy="0.0" ixz="0.0" iyy="0.001" iyz="0.0" izz="0.001"/>
    </inertial>
  </link>
  <!-- Base -->
  <joint name="base_to_torso_joint" type="fixed">
    <parent link="base_link"/>
    <origin rpy="0 0 1.570795" xyz="0 0 0"/>
    <child link="torso_link"/>
  </joint>
  <link name="base_link">
</link>
  <!-- Camera -->
  <joint name="camera_joint" type="fixed">
    <origin rpy="1.570795 0 1.570795" xyz="0 0 0.075"/>
    <parent link="base_link"/>
    <child link="camera_link"/>
  </joint>
  <link name="camera_link">
    <!--<visual>
        <geometry>
            <box size="0.01 0.01 0.01"/>
        </geometry>
        <material name="black">
            <color rgba="0.0 0.0 0.0 1.0"/>
        </material>
    </visual>
    <inertial>
      <origin xyz="0 0 0"/>
      <mass value="1.0"/>
      <inertia  ixx="0.001" ixy="0.0"  ixz="0.0"  iyy="0.001"  iyz="0.0"  izz="0.001"/>
    </inertial>-->
  </link>
  <!-- Torso -->
  <link name="torso_link">
    <visual>
      <geometry>
        <mesh filename="file:///mnt/STORAGE/Dropbox/Personal/Programming/Bioloid/CAD/BPF-CHEST-F_FCD-Conv_BDR-Col.dae" scale="0.1 0.1 0.1"/>
      </geometry>
      <origin rpy="1.570795 0 0"/>
    </visual>
    <visual>
      <geometry>
        <mesh filename="file:///mnt/STORAGE/Dropbox/Personal/Programming/Bioloid/CAD/BPF-CHEST-B_FCD-Conv_BDR-Col.dae" scale="0.1 0.1 0.1"/>
      </geometry>
      <origin rpy="1.570795 0 0"/>
    </visual>
    <visual>
      <geometry>
        <mesh filename="file:///mnt/STORAGE/Dropbox/Personal/Programming/Bioloid/CAD/CM-5_FCD-Conv_BDR-Col.dae" scale="0.1 0.1 0.1"/>
      </geometry>
      <origin rpy="0 3.14159 0" xyz="0 0.032 -0.015"/>
    </visual>
    <!-- Sensor 100 -->
    <visual>
      <geometry>
        <mesh filename="file:///mnt/STORAGE/Dropbox/Personal/Programming/Bioloid/CAD/AX-S1_FCD-Conv_BDR-Col.dae" scale="0.1 0.1 0.1"/>
      </geometry>
      <origin rpy="-1.570795 0 3.14159" xyz="0 0 0.025"/>
    </visual>
    <!-- Motor 1 -->
    <visual>
      <geometry>
        <mesh filename="file:///mnt/STORAGE/Dropbox/Personal/Programming/Bioloid/CAD/AX-12_FCD-Conv_BDR-Col.dae" scale="0.1 0.1 0.1"/>
      </geometry>
      <origin rpy="1.570795 0 -1.570795" xyz="-0.032 0 0"/>
    </visual>
    <!-- Motor 2 -->
    <visual>
      <geometry>
        <mesh filename="file:///mnt/STORAGE/Dropbox/Personal/Programming/Bioloid/CAD/AX-12_FCD-Conv_BDR-Col.dae" scale="0.1 0.1 0.1"/>
      </geometry>
      <origin rpy="1.570795 0 1.570795" xyz="0.032 0 0"/>
    </visual>
    <visual>
      <geometry>
        <mesh filename="file:///mnt/STORAGE/Dropbox/Personal/Programming/Bioloid/CAD/FP04-F8_FCD-Conv_BDR-Col.dae" scale="0.1 0.1 0.1"/>
      </geometry>
      <origin rpy="-1.570795 0 1.570795" xyz="0 0.0255 -0.0465"/>
    </visual>
    <visual>
      <geometry>
        <mesh filename="file:///mnt/STORAGE/Dropbox/Personal/Programming/Bioloid/CAD/FP04-F8_FCD-Conv_BDR-Col.dae" scale="0.1 0.1 0.1"/>
      </geometry>
      <origin rpy="1.570795 0 1.570795" xyz="0 0.0255 -0.0843"/>
    </visual>
    <!-- Motor 7 -->
    <visual>
      <geometry>
        <mesh filename="file:///mnt/STORAGE/Dropbox/Personal/Programming/Bioloid/CAD/AX-12_FCD-Conv_BDR-Col.dae" scale="0.1 0.1 0.1"/>
      </geometry>
      <origin rpy="0 3.14159 0" xyz="-0.033 0.016 -0.0655"/>
    </visual>
    <!-- Motor 8 -->
    <visual>
      <geometry>
        <mesh filename="file:///mnt/STORAGE/Dropbox/Personal/Programming/Bioloid/CAD/AX-12_FCD-Conv_BDR-Col.dae" scale="0.1 0.1 0.1"/>
      </geometry>
      <origin rpy="0 3.14159 0" xyz="0.033 0.016 -0.0655"/>
    </visual>
    <collision name="head_collision">
      <origin xyz="0 0.0122 0.035"/>
      <geometry>
        <box size="0.033 0.054 0.044"/>
      </geometry>
    </collision>
    <collision name="torso_collision_top">
      <origin xyz="0 0.019 -0.015"/>
      <geometry>
        <box size="0.103 0.0905 0.0635"/>
      </geometry>
    </collision>
    <collision name="torso_collision_bottom">
      <origin xyz="0 0.00625 -0.0648"/>
      <geometry>
        <box size="0.099 0.065 0.043"/>
      </geometry>
    </collision>
    <inertial>
      <origin xyz="0 0 0"/>
      <mass value="1.0"/>
      <inertia ixx="0.001" ixy="0.0" ixz="0.0" iyy="0.001" iyz="0.0" izz="0.001"/>
    </inertial>
  </link>
  <!-- Torso to right shoulder -->
  <joint name="right_shoulder_swing_joint" type="revolute">
    <parent link="torso_link"/>
    <origin rpy="0 -1.570795 0.0" xyz="-0.032 0 0"/>
    <axis xyz="0 0 1"/>
    <child link="right_shoulder_swing_link"/>
    <limit effort="10" lower="-3.14159" upper="3.14159" velocity="1.0"/>
  </joint>
  <link name="right_shoulder_swing_link">
    <visual>
      <geometry>
        <mesh filename="file:///mnt/STORAGE/Dropbox/Personal/Programming/Bioloid/CAD/FP04-F1_FCD-Conv_BDR-Col.dae" scale="0.1 0.1 0.1"/>
      </geometry>
      <origin rpy="0 3.14159 -1.570795" xyz="-0.014 0 0.044"/>
    </visual>
    <collision name="right_shoulder_collision">
      <origin xyz="-0.006 0 0.0375"/>
      <geometry>
        <box size="0.039 0.052 0.036"/>
      </geometry>
    </collision>
    <inertial>
      <origin xyz="0 0 0"/>
      <mass value="1.0"/>
      <inertia ixx="0.001" ixy="0.0" ixz="0.0" iyy="0.001" iyz="0.0" izz="0.001"/>
    </inertial>
  </link>
  <!-- Torso to left shoulder -->
  <joint name="left_shoulder_swing_joint" type="revolute">
    <parent link="torso_link"/>
    <origin rpy="0 1.570795 3.14159" xyz="0.032 0 0"/>
    <axis xyz="0 0 1"/>
    <child link="left_shoulder_swing_link"/>
    <limit effort="10" lower="-3.14159" upper="3.14159" velocity="1.0"/>
  </joint>
  <link name="left_shoulder_swing_link">
    <visual>
      <geometry>
        <mesh filename="file:///mnt/STORAGE/Dropbox/Personal/Programming/Bioloid/CAD/FP04-F1_FCD-Conv_BDR-Col.dae" scale="0.1 0.1 0.1"/>
      </geometry>
      <origin rpy="0 0 1.570795" xyz="0.014 0 -0.044"/>
    </visual>
    <collision name="left_shoulder_collision">
      <origin xyz="0.006 0 -0.0375"/>
      <geometry>
        <box size="0.039 0.052 0.036"/>
      </geometry>
    </collision>
    <inertial>
      <origin xyz="0 0 0"/>
      <mass value="1.0"/>
      <inertia ixx="0.001" ixy="0.0" ixz="0.0" iyy="0.001" iyz="0.0" izz="0.001"/>
    </inertial>
  </link>
  <!-- Right shoulder to upper arm -->
  <joint name="right_shoulder_lateral_joint" type="revolute">
    <parent link="right_shoulder_swing_link"/>
    <origin rpy="-1.570795 0 0" xyz="-0.014 0 0.044"/>
    <axis xyz="0 0 1"/>
    <child link="right_upper_arm_link"/>
    <limit effort="10" lower="-0.2" upper="3.14159" velocity="1.0"/>
  </joint>
  <link name="right_upper_arm_link">
    <visual>
      <geometry>
        <mesh filename="file:///mnt/STORAGE/Dropbox/Personal/Programming/Bioloid/CAD/AX-12_FCD-Conv_BDR-Col.dae" scale="0.1 0.1 0.1"/>
      </geometry>
      <origin rpy="3.14159 0 1.570795" xyz="0 0 0"/>
    </visual>
    <visual>
      <geometry>
        <mesh filename="file:///mnt/STORAGE/Dropbox/Personal/Programming/Bioloid/CAD/BPF-BU_FCD-Conv_BDR-Col.dae" scale="0.1 0.1 0.1"/>
      </geometry>
      <origin rpy="1.570795 0 0" xyz="0 0 0.0185"/>
    </visual>
    <visual>
      <geometry>
        <mesh filename="file:///mnt/STORAGE/Dropbox/Personal/Programming/Bioloid/CAD/BPF-WA_FCD-Conv_BDR-Col.dae" scale="0.1 0.1 0.1"/>
      </geometry>
      <origin rpy="1.570795 0 0" xyz="0 0 0.019"/>
    </visual>
    <visual>
      <geometry>
        <mesh filename="file:///mnt/STORAGE/Dropbox/Personal/Programming/Bioloid/CAD/FP04-F3_FCD-Conv_BDR-Col.dae" scale="0.1 0.1 0.1"/>
      </geometry>
      <origin rpy="0 0 -1.570795" xyz="-0.0415 0 0"/>
    </visual>
    <visual>
      <geometry>
        <mesh filename="file:///mnt/STORAGE/Dropbox/Personal/Programming/Bioloid/CAD/FP04-F2_FCD-Conv_BDR-Col.dae" scale="0.1 0.1 0.1"/>
      </geometry>
      <origin rpy="0 1.570795 0" xyz="-0.0675 0 0"/>
    </visual>
    <collision name="right_upper arm_collision_proximal">
      <origin xyz="-0.0148 0 0"/>
      <geometry>
        <box size="0.054 0.033 0.044"/>
      </geometry>
    </collision>
    <collision name="right_upper arm_collision_distal">
      <origin xyz="-0.0555 0 0"/>
      <geometry>
        <box size="0.047 0.033 0.052"/>
      </geometry>
    </collision>
    <inertial>
      <origin xyz="0 0 0"/>
      <mass value="1.0"/>
      <inertia ixx="0.001" ixy="0.0" ixz="0.0" iyy="0.001" iyz="0.0" izz="0.001"/>
    </inertial>
  </link>
  <!-- Left shoulder to upper arm -->
  <joint name="left_shoulder_lateral_joint" type="revolute">
    <parent link="left_shoulder_swing_link"/>
    <origin rpy="-1.570795 0 0" xyz="0.014 0 -0.044"/>
    <axis xyz="0 0 1"/>
    <child link="left_upper_arm_link"/>
    <limit effort="10" lower="-0.2" upper="3.14159" velocity="1.0"/>
  </joint>
  <link name="left_upper_arm_link">
    <visual>
      <geometry>
        <mesh filename="file:///mnt/STORAGE/Dropbox/Personal/Programming/Bioloid/CAD/AX-12_FCD-Conv_BDR-Col.dae" scale="0.1 0.1 0.1"/>
      </geometry>
      <origin rpy="0 0 1.570795" xyz="0 0 0"/>
    </visual>
    <visual>
      <geometry>
        <mesh filename="file:///mnt/STORAGE/Dropbox/Personal/Programming/Bioloid/CAD/BPF-BU_FCD-Conv_BDR-Col.dae" scale="0.1 0.1 0.1"/>
      </geometry>
      <origin rpy="-1.570795 0 0" xyz="0 0 -0.0185"/>
    </visual>
    <visual>
      <geometry>
        <mesh filename="file:///mnt/STORAGE/Dropbox/Personal/Programming/Bioloid/CAD/BPF-WA_FCD-Conv_BDR-Col.dae" scale="0.1 0.1 0.1"/>
      </geometry>
      <origin rpy="-1.570795 0 0" xyz="0 0 -0.019"/>
    </visual>
    <visual>
      <geometry>
        <mesh filename="file:///mnt/STORAGE/Dropbox/Personal/Programming/Bioloid/CAD/FP04-F3_FCD-Conv_BDR-Col.dae" scale="0.1 0.1 0.1"/>
      </geometry>
      <origin rpy="0 0 1.570795" xyz="0.0415 0 0"/>
    </visual>
    <visual>
      <geometry>
        <mesh filename="file:///mnt/STORAGE/Dropbox/Personal/Programming/Bioloid/CAD/FP04-F2_FCD-Conv_BDR-Col.dae" scale="0.1 0.1 0.1"/>
      </geometry>
      <origin rpy="0 -1.570795 0" xyz="0.0675 0 0"/>
    </visual>
    <collision name="left_upper arm_collision_proximal">
      <origin xyz="0.0148 0 0"/>
      <geometry>
        <box size="0.054 0.033 0.044"/>
      </geometry>
    </collision>
    <collision name="left_upper arm_collision_distal">
      <origin xyz="0.0555 0 0"/>
      <geometry>
        <box size="0.047 0.033 0.052"/>
      </geometry>
    </collision>
    <inertial>
      <origin xyz="0 0 0"/>
      <mass value="1.0"/>
      <inertia ixx="0.001" ixy="0.0" ixz="0.0" iyy="0.001" iyz="0.0" izz="0.001"/>
    </inertial>
  </link>
  <!-- Right upper arm to lower arm -->
  <joint name="right_elbow_joint" type="revolute">
    <parent link="right_upper_arm_link"/>
    <origin rpy="0 0 0" xyz="-0.0675 0 0"/>
    <axis xyz="0 0 1"/>
    <child link="right_lower_arm_link"/>
    <limit effort="10" lower="-1.77" upper="1.77" velocity="1.0"/>
  </joint>
  <link name="right_lower_arm_link">
    <!-- Motor 5 -->
    <visual>
      <geometry>
        <mesh filename="file:///mnt/STORAGE/Dropbox/Personal/Programming/Bioloid/CAD/AX-12_FCD-Conv_BDR-Col.dae" scale="0.1 0.1 0.1"/>
      </geometry>
      <origin rpy="3.14159 0 1.570795" xyz="0 0 0"/>
    </visual>
    <visual>
      <geometry>
        <mesh filename="file:///mnt/STORAGE/Dropbox/Personal/Programming/Bioloid/CAD/BPF-BU_FCD-Conv_BDR-Col.dae" scale="0.1 0.1 0.1"/>
      </geometry>
      <origin rpy="1.570795 0 0" xyz="0 0 0.0185"/>
    </visual>
    <visual>
      <geometry>
        <mesh filename="file:///mnt/STORAGE/Dropbox/Personal/Programming/Bioloid/CAD/BPF-WA_FCD-Conv_BDR-Col.dae" scale="0.1 0.1 0.1"/>
      </geometry>
      <origin rpy="1.570795 0 0" xyz="0 0 0.019"/>
    </visual>
    <visual>
      <geometry>
        <mesh filename="file:///mnt/STORAGE/Dropbox/Personal/Programming/Bioloid/CAD/FP04-F3_FCD-Conv_BDR-Col.dae" scale="0.1 0.1 0.1"/>
      </geometry>
      <origin rpy="0 0 -1.570795" xyz="-0.0415 0 0"/>
    </visual>
    <collision name="right_lower_arm_collision">
      <origin xyz="-0.0135 0 0"/>
      <geometry>
        <box size="0.051 0.033 0.044"/>
      </geometry>
    </collision>
    <inertial>
      <origin xyz="0 0 0"/>
      <mass value="1.0"/>
      <inertia ixx="0.001" ixy="0.0" ixz="0.0" iyy="0.001" iyz="0.0" izz="0.001"/>
    </inertial>
  </link>
  <!-- Right lower arm to hand -->
  <joint name="right_hand_joint" type="fixed">
    <parent link="right_lower_arm_link"/>
    <origin rpy="0 0 0" xyz="0 0 0"/>
    <child link="right_hand_link"/>
  </joint>
  <link name="right_hand_link">
    <visual>
      <geometry>
        <mesh filename="file:///mnt/STORAGE/Dropbox/Personal/Programming/Bioloid/CAD/FP04-F11_FCD-Conv_BDR-Col.dae" scale="0.1 0.1 0.1"/>
      </geometry>
      <origin rpy="-3.14159 1.570795 0" xyz="-0.0415 0 0"/>
    </visual>
    <collision name="right_palm_collision">
      <origin xyz="-0.039 0 0"/>
      <geometry>
        <box size="0.0131 0.0265 0.044"/>
      </geometry>
    </collision>
    <collision name="right_fingers_collision">
      <origin xyz="-0.0701 -0.0077 0"/>
      <geometry>
        <box size="0.0575 0.0175 0.035"/>
      </geometry>
    </collision>
    <inertial>
      <origin xyz="0 0 0"/>
      <mass value="1.0"/>
      <inertia ixx="0.001" ixy="0.0" ixz="0.0" iyy="0.001" iyz="0.0" izz="0.001"/>
    </inertial>
  </link>
  <!-- Left upper arm to lower arm -->
  <joint name="left_elbow_joint" type="revolute">
    <parent link="left_upper_arm_link"/>
    <origin rpy="0 0 0" xyz="0.0675 0 0"/>
    <axis xyz="0 0 1"/>
    <child link="left_lower_arm_link"/>
    <limit effort="10" lower="-1.77" upper="1.77" velocity="1.0"/>
  </joint>
  <link name="left_lower_arm_link">
    <!-- Motor 6 -->
    <visual>
      <geometry>
        <mesh filename="file:///mnt/STORAGE/Dropbox/Personal/Programming/Bioloid/CAD/AX-12_FCD-Conv_BDR-Col.dae" scale="0.1 0.1 0.1"/>
      </geometry>
      <origin rpy="0 0 1.570795" xyz="0 0 0"/>
    </visual>
    <visual>
      <geometry>
        <mesh filename="file:///mnt/STORAGE/Dropbox/Personal/Programming/Bioloid/CAD/BPF-BU_FCD-Conv_BDR-Col.dae" scale="0.1 0.1 0.1"/>
      </geometry>
      <origin rpy="-1.570795 0 0" xyz="0 0 -0.0185"/>
    </visual>
    <visual>
      <geometry>
        <mesh filename="file:///mnt/STORAGE/Dropbox/Personal/Programming/Bioloid/CAD/BPF-WA_FCD-Conv_BDR-Col.dae" scale="0.1 0.1 0.1"/>
      </geometry>
      <origin rpy="-1.570795 0 0" xyz="0 0 -0.019"/>
    </visual>
    <visual>
      <geometry>
        <mesh filename="file:///mnt/STORAGE/Dropbox/Personal/Programming/Bioloid/CAD/FP04-F3_FCD-Conv_BDR-Col.dae" scale="0.1 0.1 0.1"/>
      </geometry>
      <origin rpy="0 0 1.570795" xyz="0.0415 0 0"/>
    </visual>
    <collision name="left_lower_arm_collision">
      <origin xyz="0.017 0 0"/>
      <geometry>
        <box size="0.058 0.033 0.044"/>
      </geometry>
    </collision>
    <inertial>
      <origin xyz="0 0 0"/>
      <mass value="1.0"/>
      <inertia ixx="0.001" ixy="0.0" ixz="0.0" iyy="0.001" iyz="0.0" izz="0.001"/>
    </inertial>
  </link>
  <!-- Left lower arm to hand -->
  <joint name="left_hand_joint" type="fixed">
    <parent link="left_lower_arm_link"/>
    <origin rpy="0 0 0" xyz="0 0 0"/>
    <child link="left_hand_link"/>
  </joint>
  <link name="left_hand_link">
    <visual>
      <geometry>
        <mesh filename="file:///mnt/STORAGE/Dropbox/Personal/Programming/Bioloid/CAD/FP04-F11_FCD-Conv_BDR-Col.dae" scale="0.1 0.1 0.1"/>
      </geometry>
      <origin rpy="0 1.570795 0" xyz="0.0415 0 0"/>
    </visual>
    <collision name="left_palm_collision">
      <origin xyz="0.039 0 0"/>
      <geometry>
        <box size="0.0131 0.0265 0.044"/>
      </geometry>
    </collision>
    <collision name="left_fingers_collision">
      <origin xyz="0.0701 0.0077 0"/>
      <geometry>
        <box size="0.0575 0.0175 0.035"/>
      </geometry>
    </collision>
    <inertial>
      <origin xyz="0 0 0"/>
      <mass value="1.0"/>
      <inertia ixx="0.001" ixy="0.0" ixz="0.0" iyy="0.001" iyz="0.0" izz="0.001"/>
    </inertial>
  </link>
  <!-- Torso to right hip twist -->
  <joint name="right_hip_twist_joint" type="revolute">
    <parent link="torso_link"/>
    <origin rpy="3.14159 0 0.0" xyz="-0.033 0.016 -0.0655"/>
    <axis xyz="0 0 1"/>
    <child link="right_hip_twist_link"/>
    <limit effort="10" lower="-0.7853975" upper="0.7853975" velocity="1.0"/>
  </joint>
  <link name="right_hip_twist_link">
    <visual>
      <geometry>
        <mesh filename="file:///mnt/STORAGE/Dropbox/Personal/Programming/Bioloid/CAD/FP04-F5_FCD-Conv_BDR-Col.dae" scale="0.1 0.1 0.1"/>
      </geometry>
      <origin rpy="3.14159 0 0" xyz="0 0 0.05"/>
    </visual>
    <collision name="right_hip_twist_collision">
      <origin xyz="0 0.0008 0.041"/>
      <geometry>
        <box size="0.029 0.083 0.0405"/>
      </geometry>
    </collision>
    <inertial>
      <origin xyz="0 0 0"/>
      <mass value="1.0"/>
      <inertia ixx="0.001" ixy="0.0" ixz="0.0" iyy="0.001" iyz="0.0" izz="0.001"/>
    </inertial>
  </link>
  <!-- Torso to left hip twist -->
  <joint name="left_hip_twist_joint" type="revolute">
    <parent link="torso_link"/>
    <origin rpy="0.0 0 3.14159" xyz="0.033 0.016 -0.0655"/>
    <axis xyz="0 0 1"/>
    <child link="left_hip_twist_link"/>
    <limit effort="10" lower="-0.7853975" upper="0.7853975" velocity="1.0"/>
  </joint>
  <link name="left_hip_twist_link">
    <visual>
      <geometry>
        <mesh filename="file:///mnt/STORAGE/Dropbox/Personal/Programming/Bioloid/CAD/FP04-F5_FCD-Conv_BDR-Col.dae" scale="0.1 0.1 0.1"/>
      </geometry>
      <origin rpy="0 0 0" xyz="0 0 -0.05"/>
    </visual>
    <collision name="left_hip_twist_collision">
      <origin xyz="0 0.0008 -0.041"/>
      <geometry>
        <box size="0.029 0.083 0.0405"/>
      </geometry>
    </collision>
    <inertial>
      <origin xyz="0 0 0"/>
      <mass value="1.0"/>
      <inertia ixx="0.001" ixy="0.0" ixz="0.0" iyy="0.001" iyz="0.0" izz="0.001"/>
    </inertial>
  </link>
  <!-- Right hip twist to hip lateral -->
  <joint name="right_hip_lateral_joint" type="revolute">
    <parent link="right_hip_twist_link"/>
    <origin rpy="1.570795 0 0" xyz="0 -0.0153 0.05"/>
    <axis xyz="0 0 1"/>
    <child link="right_hip_lateral_link"/>
    <limit effort="10" lower="-0.3" upper="0.3" velocity="1.0"/>
  </joint>
  <link name="right_hip_lateral_link">
    <!-- Motor 9 -->
    <visual>
      <geometry>
        <mesh filename="file:///mnt/STORAGE/Dropbox/Personal/Programming/Bioloid/CAD/AX-12_FCD-Conv_BDR-Col.dae" scale="0.1 0.1 0.1"/>
      </geometry>
      <origin rpy="0 0 3.14159" xyz="0 0 0"/>
    </visual>
    <visual>
      <geometry>
        <mesh filename="file:///mnt/STORAGE/Dropbox/Personal/Programming/Bioloid/CAD/FP04-F6_FCD-Conv_BDR-Col.dae" scale="0.1 0.1 0.1"/>
      </geometry>
      <origin rpy="0 -1.570795 -1.570795" xyz="-0.019 0.0145 0.016"/>
    </visual>
    <visual>
      <geometry>
        <mesh filename="file:///mnt/STORAGE/Dropbox/Personal/Programming/Bioloid/CAD/FP04-F6_FCD-Conv_BDR-Col.dae" scale="0.1 0.1 0.1"/>
      </geometry>
      <origin rpy="0 -1.570795 1.570795" xyz="0.019 0.0145 0.016"/>
    </visual>
    <!-- Motor 11 -->
    <visual>
      <geometry>
        <mesh filename="file:///mnt/STORAGE/Dropbox/Personal/Programming/Bioloid/CAD/AX-12_FCD-Conv_BDR-Col.dae" scale="0.1 0.1 0.1"/>
      </geometry>
      <origin rpy="3.14159 -1.570795 0" xyz="0 0 -0.032"/>
    </visual>
    <visual>
      <geometry>
        <mesh filename="file:///mnt/STORAGE/Dropbox/Personal/Programming/Bioloid/CAD/BPF-BU_FCD-Conv_BDR-Col.dae" scale="0.1 0.1 0.1"/>
      </geometry>
      <origin rpy="-1.570795 0 0" xyz="0 0 -0.05"/>
    </visual>
    <visual>
      <geometry>
        <mesh filename="file:///mnt/STORAGE/Dropbox/Personal/Programming/Bioloid/CAD/FP04-F7_FCD-Conv_BDR-Col.dae" scale="0.1 0.1 0.1"/>
      </geometry>
      <origin rpy="1.570795 0 -1.570795" xyz="0 0.0145 -0.051"/>
    </visual>
    <collision name="right_hip_lateral_collision">
      <origin xyz="0 0.0135 -0.0153"/>
      <geometry>
        <box size="0.04 0.051 0.0721"/>
      </geometry>
    </collision>
    <inertial>
      <origin xyz="0 0 0"/>
      <mass value="1.0"/>
      <inertia ixx="0.001" ixy="0.0" ixz="0.0" iyy="0.001" iyz="0.0" izz="0.001"/>
    </inertial>
  </link>
  <!-- Left hip twist to hip lateral -->
  <joint name="left_hip_lateral_joint" type="revolute">
    <parent link="left_hip_twist_link"/>
    <origin rpy="-1.570795 0 0" xyz="0 -0.0153 -0.05"/>
    <axis xyz="0 0 1"/>
    <child link="left_hip_lateral_link"/>
    <limit effort="10" lower="-0.3" upper="0.3" velocity="1.0"/>
  </joint>
  <link name="left_hip_lateral_link">
    <!-- Motor 10 -->
    <visual>
      <geometry>
        <mesh filename="file:///mnt/STORAGE/Dropbox/Personal/Programming/Bioloid/CAD/AX-12_FCD-Conv_BDR-Col.dae" scale="0.1 0.1 0.1"/>
      </geometry>
      <origin rpy="3.14159 0 0" xyz="0 0 0"/>
    </visual>
    <visual>
      <geometry>
        <mesh filename="file:///mnt/STORAGE/Dropbox/Personal/Programming/Bioloid/CAD/FP04-F6_FCD-Conv_BDR-Col.dae" scale="0.1 0.1 0.1"/>
      </geometry>
      <origin rpy="0 1.570795 -1.570795" xyz="-0.019 0.0145 -0.016"/>
    </visual>
    <visual>
      <geometry>
        <mesh filename="file:///mnt/STORAGE/Dropbox/Personal/Programming/Bioloid/CAD/FP04-F6_FCD-Conv_BDR-Col.dae" scale="0.1 0.1 0.1"/>
      </geometry>
      <origin rpy="0 1.570795 1.570795" xyz="0.019 0.0145 -0.016"/>
    </visual>
    <!-- Motor 12 -->
    <visual>
      <geometry>
        <mesh filename="file:///mnt/STORAGE/Dropbox/Personal/Programming/Bioloid/CAD/AX-12_FCD-Conv_BDR-Col.dae" scale="0.1 0.1 0.1"/>
      </geometry>
      <origin rpy="3.14159 -1.570795 0" xyz="0 0 0.032"/>
    </visual>
    <visual>
      <geometry>
        <mesh filename="file:///mnt/STORAGE/Dropbox/Personal/Programming/Bioloid/CAD/BPF-BU_FCD-Conv_BDR-Col.dae" scale="0.1 0.1 0.1"/>
      </geometry>
      <origin rpy="1.570795 0 0" xyz="0 0 0.05"/>
    </visual>
    <visual>
      <geometry>
        <mesh filename="file:///mnt/STORAGE/Dropbox/Personal/Programming/Bioloid/CAD/FP04-F7_FCD-Conv_BDR-Col.dae" scale="0.1 0.1 0.1"/>
      </geometry>
      <origin rpy="-1.570795 0 -1.570795" xyz="0 0.0145 0.051"/>
    </visual>
    <collision name="left_hip_lateral_collision">
      <origin xyz="0 0.0135 0.0153"/>
      <geometry>
        <box size="0.04 0.051 0.0721"/>
      </geometry>
    </collision>
    <inertial>
      <origin xyz="0 0 0"/>
      <mass value="1.0"/>
      <inertia ixx="0.001" ixy="0.0" ixz="0.0" iyy="0.001" iyz="0.0" izz="0.001"/>
    </inertial>
  </link>
  <!-- Right hip lateral to upper leg -->
  <joint name="right_hip_swing_joint" type="revolute">
    <parent link="right_hip_lateral_link"/>
    <origin rpy="0.0 -1.570795 0" xyz="0 0 -0.032"/>
    <axis xyz="0 0 1"/>
    <child link="right_upper_leg_link"/>
    <limit effort="10" lower="-1.570795" upper="1.570795" velocity="1.0"/>
  </joint>
  <link name="right_upper_leg_link">
    <visual>
      <geometry>
        <mesh filename="file:///mnt/STORAGE/Dropbox/Personal/Programming/Bioloid/CAD/FP04-F4_FCD-Conv_BDR-Col.dae" scale="0.1 0.1 0.1"/>
      </geometry>
      <origin rpy="-1.570795 1.570795 0" xyz="0 0 0"/>
    </visual>
    <visual>
      <geometry>
        <mesh filename="file:///mnt/STORAGE/Dropbox/Personal/Programming/Bioloid/CAD/FP04-F1_FCD-Conv_BDR-Col.dae" scale="0.1 0.1 0.1"/>
      </geometry>
      <origin rpy="1.570795 -1.570795 0" xyz="0.0145 0.075 0"/>
    </visual>
    <collision name="right_upper_leg_proximal_collision">
      <origin xyz="0 0.0214 0"/>
      <geometry>
        <box size="0.03 0.065 0.049"/>
      </geometry>
    </collision>
    <collision name="right_upper_leg_distal_collision">
      <origin xyz="0.0065 0.0675 0"/>
      <geometry>
        <box size="0.04 0.0371 0.049"/>
      </geometry>
    </collision>
    <inertial>
      <origin xyz="0 0 0"/>
      <mass value="1.0"/>
      <inertia ixx="0.001" ixy="0.0" ixz="0.0" iyy="0.001" iyz="0.0" izz="0.001"/>
    </inertial>
  </link>
  <!-- Left hip lateral to upper leg -->
  <joint name="left_hip_swing_joint" type="revolute">
    <parent link="left_hip_lateral_link"/>
    <origin rpy="3.14159 -1.570795 0" xyz="0 0 0.032"/>
    <axis xyz="0 0 1"/>
    <child link="left_upper_leg_link"/>
    <limit effort="10" lower="-1.570795" upper="1.570795" velocity="1.0"/>
  </joint>
  <link name="left_upper_leg_link">
    <visual>
      <geometry>
        <mesh filename="file:///mnt/STORAGE/Dropbox/Personal/Programming/Bioloid/CAD/FP04-F4_FCD-Conv_BDR-Col.dae" scale="0.1 0.1 0.1"/>
      </geometry>
      <origin rpy="1.570795 1.570795 0" xyz="0 0 0"/>
    </visual>
    <visual>
      <geometry>
        <mesh filename="file:///mnt/STORAGE/Dropbox/Personal/Programming/Bioloid/CAD/FP04-F1_FCD-Conv_BDR-Col.dae" scale="0.1 0.1 0.1"/>
      </geometry>
      <origin rpy="-1.570795 -1.570795 0" xyz="-0.0145 -0.075 0"/>
    </visual>
    <collision name="left_upper_leg_proximal_collision">
      <origin xyz="0 -0.0214 0"/>
      <geometry>
        <box size="0.03 0.065 0.049"/>
      </geometry>
    </collision>
    <collision name="left_upper_leg_distal_collision">
      <origin xyz="-0.0065 -0.0675 0"/>
      <geometry>
        <box size="0.04 0.0371 0.049"/>
      </geometry>
    </collision>
    <inertial>
      <origin xyz="0 0 0"/>
      <mass value="1.0"/>
      <inertia ixx="0.001" ixy="0.0" ixz="0.0" iyy="0.001" iyz="0.0" izz="0.001"/>
    </inertial>
  </link>
  <!-- Right upper leg to lower leg -->
  <joint name="right_knee_joint" type="revolute">
    <parent link="right_upper_leg_link"/>
    <origin rpy="0 0 0" xyz="0.0145 0.075 0"/>
    <axis xyz="0 0 1"/>
    <child link="right_lower_leg_link"/>
    <limit effort="10" lower="-3.14159" upper="0.0" velocity="1.0"/>
  </joint>
  <link name="right_lower_leg_link">
    <!-- Motor 13 -->
    <visual>
      <geometry>
        <mesh filename="file:///mnt/STORAGE/Dropbox/Personal/Programming/Bioloid/CAD/AX-12_FCD-Conv_BDR-Col.dae" scale="0.1 0.1 0.1"/>
      </geometry>
      <origin rpy="0 3.14159 -1.570795" xyz="0 0 0"/>
    </visual>
    <visual>
      <geometry>
        <mesh filename="file:///mnt/STORAGE/Dropbox/Personal/Programming/Bioloid/CAD/FP04-F3_FCD-Conv_BDR-Col.dae" scale="0.1 0.1 0.1"/>
      </geometry>
      <origin rpy="0 0 3.14159" xyz="-0.0145 0.019 0"/>
    </visual>
    <visual>
      <geometry>
        <mesh filename="file:///mnt/STORAGE/Dropbox/Personal/Programming/Bioloid/CAD/FP04-F4_FCD-Conv_BDR-Col.dae" scale="0.1 0.1 0.1"/>
      </geometry>
      <origin rpy="1.570795 -1.570795 0" xyz="-0.0145 0.071 0"/>
    </visual>
    <collision name="right_lower_leg_proximal_collision">
      <origin xyz="-0.0135 0 0"/>
      <geometry>
        <box size="0.051 0.033 0.044"/>
      </geometry>
    </collision>
    <collision name="right_lower_leg_distal_collision">
      <origin xyz="-0.0145 0.0492 0"/>
      <geometry>
        <box size="0.03 0.067 0.049"/>
      </geometry>
    </collision>
    <inertial>
      <origin xyz="0 0 0"/>
      <mass value="1.0"/>
      <inertia ixx="0.001" ixy="0.0" ixz="0.0" iyy="0.001" iyz="0.0" izz="0.001"/>
    </inertial>
  </link>
  <!-- Left upper leg to lower leg -->
  <joint name="left_knee_joint" type="revolute">
    <parent link="left_upper_leg_link"/>
    <origin rpy="0 0 0" xyz="-0.0145 -0.075 0"/>
    <axis xyz="0 0 1"/>
    <child link="left_lower_leg_link"/>
    <limit effort="10" lower="-3.14159" upper="0.0" velocity="1.0"/>
  </joint>
  <link name="left_lower_leg_link">
    <!-- Motor 14 -->
    <visual>
      <geometry>
        <mesh filename="file:///mnt/STORAGE/Dropbox/Personal/Programming/Bioloid/CAD/AX-12_FCD-Conv_BDR-Col.dae" scale="0.1 0.1 0.1"/>
      </geometry>
      <origin rpy="0 0 1.570795" xyz="0 0 0"/>
    </visual>
    <visual>
      <geometry>
        <mesh filename="file:///mnt/STORAGE/Dropbox/Personal/Programming/Bioloid/CAD/FP04-F3_FCD-Conv_BDR-Col.dae" scale="0.1 0.1 0.1"/>
      </geometry>
      <origin rpy="0 0 0" xyz="0.0145 -0.019 0"/>
    </visual>
    <visual>
      <geometry>
        <mesh filename="file:///mnt/STORAGE/Dropbox/Personal/Programming/Bioloid/CAD/FP04-F4_FCD-Conv_BDR-Col.dae" scale="0.1 0.1 0.1"/>
      </geometry>
      <origin rpy="-1.570795 -1.570795 0" xyz="0.0145 -0.071 0"/>
    </visual>
    <collision name="left_lower_leg_proximal_collision">
      <origin xyz="0.0135 0 0"/>
      <geometry>
        <box size="0.051 0.033 0.044"/>
      </geometry>
    </collision>
    <collision name="left_lower_leg_distal_collision">
      <origin xyz="0.0145 -0.0492 0"/>
      <geometry>
        <box size="0.03 0.067 0.049"/>
      </geometry>
    </collision>
    <inertial>
      <origin xyz="0 0 0"/>
      <mass value="1.0"/>
      <inertia ixx="0.001" ixy="0.0" ixz="0.0" iyy="0.001" iyz="0.0" izz="0.001"/>
    </inertial>
  </link>
  <!-- Right lower leg to ankle swing -->
  <joint name="right_ankle_swing_joint" type="revolute">
    <parent link="right_lower_leg_link"/>
    <origin rpy="0 0 0" xyz="-0.0145 0.071 0"/>
    <axis xyz="0 0 1"/>
    <child link="right_ankle_swing_link"/>
    <limit effort="10" lower="-0.45" upper="1.570795" velocity="1.0"/>
  </joint>
  <link name="right_ankle_swing_link">
    <!-- Motor 15 -->
    <visual>
      <geometry>
        <mesh filename="file:///mnt/STORAGE/Dropbox/Personal/Programming/Bioloid/CAD/AX-12_FCD-Conv_BDR-Col.dae" scale="0.1 0.1 0.1"/>
      </geometry>
      <origin rpy="0 3.14159 0" xyz="0 0 0"/>
    </visual>
    <visual>
      <geometry>
        <mesh filename="file:///mnt/STORAGE/Dropbox/Personal/Programming/Bioloid/CAD/FP04-F7_FCD-Conv_BDR-Col.dae" scale="0.1 0.1 0.1"/>
      </geometry>
      <origin rpy="3.14159 0 1.570795" xyz="-0.019 -0.0145 0"/>
    </visual>
    <!-- Motor 17 -->
    <visual>
      <geometry>
        <mesh filename="file:///mnt/STORAGE/Dropbox/Personal/Programming/Bioloid/CAD/AX-12_FCD-Conv_BDR-Col.dae" scale="0.1 0.1 0.1"/>
      </geometry>
      <origin rpy="0 1.570795 0" xyz="0.032 0 0"/>
    </visual>
    <visual>
      <geometry>
        <mesh filename="file:///mnt/STORAGE/Dropbox/Personal/Programming/Bioloid/CAD/FP04-F6_FCD-Conv_BDR-Col.dae" scale="0.1 0.1 0.1"/>
      </geometry>
      <origin rpy="-1.570795 0 0" xyz="0.048 -0.0145 0.019"/>
    </visual>
    <visual>
      <geometry>
        <mesh filename="file:///mnt/STORAGE/Dropbox/Personal/Programming/Bioloid/CAD/FP04-F6_FCD-Conv_BDR-Col.dae" scale="0.1 0.1 0.1"/>
      </geometry>
      <origin rpy="1.570795 0 0" xyz="0.048 -0.0145 -0.019"/>
    </visual>
    <collision name="right_ankle_swing_collision">
      <origin xyz="0.0167 -0.0135 0"/>
      <geometry>
        <box size="0.0721 0.051 0.04"/>
      </geometry>
    </collision>
    <inertial>
      <origin xyz="0 0 0"/>
      <mass value="1.0"/>
      <inertia ixx="0.001" ixy="0.0" ixz="0.0" iyy="0.001" iyz="0.0" izz="0.001"/>
    </inertial>
  </link>
  <!-- Left lower leg to ankle swing -->
  <joint name="left_ankle_swing_joint" type="revolute">
    <parent link="left_lower_leg_link"/>
    <origin rpy="0 0 0" xyz="0.0145 -0.071 0"/>
    <axis xyz="0 0 1"/>
    <child link="left_ankle_swing_link"/>
    <limit effort="10" lower="-0.45" upper="1.570795" velocity="1.0"/>
  </joint>
  <link name="left_ankle_swing_link">
    <!-- Motor 16 -->
    <visual>
      <geometry>
        <mesh filename="file:///mnt/STORAGE/Dropbox/Personal/Programming/Bioloid/CAD/AX-12_FCD-Conv_BDR-Col.dae" scale="0.1 0.1 0.1"/>
      </geometry>
      <origin rpy="0 0 3.14159" xyz="0 0 0"/>
    </visual>
    <visual>
      <geometry>
        <mesh filename="file:///mnt/STORAGE/Dropbox/Personal/Programming/Bioloid/CAD/FP04-F7_FCD-Conv_BDR-Col.dae" scale="0.1 0.1 0.1"/>
      </geometry>
      <origin rpy="3.14159 0 -1.570795" xyz="0.019 0.0145 0"/>
    </visual>
    <!-- Motor 18 -->
    <visual>
      <geometry>
        <mesh filename="file:///mnt/STORAGE/Dropbox/Personal/Programming/Bioloid/CAD/AX-12_FCD-Conv_BDR-Col.dae" scale="0.1 0.1 0.1"/>
      </geometry>
      <origin rpy="3.14159 1.570795 0" xyz="-0.032 0 0"/>
    </visual>
    <visual>
      <geometry>
        <mesh filename="file:///mnt/STORAGE/Dropbox/Personal/Programming/Bioloid/CAD/FP04-F6_FCD-Conv_BDR-Col.dae" scale="0.1 0.1 0.1"/>
      </geometry>
      <origin rpy="1.570795 0 3.14159" xyz="-0.048 0.0145 -0.019"/>
    </visual>
    <visual>
      <geometry>
        <mesh filename="file:///mnt/STORAGE/Dropbox/Personal/Programming/Bioloid/CAD/FP04-F6_FCD-Conv_BDR-Col.dae" scale="0.1 0.1 0.1"/>
      </geometry>
      <origin rpy="-1.570795 0 3.14159" xyz="-0.048 0.0145 0.019"/>
    </visual>
    <collision name="left_ankle_swing_collision">
      <origin xyz="-0.0167 0.0135 0"/>
      <geometry>
        <box size="0.0721 0.051 0.04"/>
      </geometry>
    </collision>
    <inertial>
      <origin xyz="0 0 0"/>
      <mass value="1.0"/>
      <inertia ixx="0.001" ixy="0.0" ixz="0.0" iyy="0.001" iyz="0.0" izz="0.001"/>
    </inertial>
  </link>
  <!-- Right ankle swing to ankle lateral -->
  <joint name="right_ankle_lateral_joint" type="revolute">
    <parent link="right_ankle_swing_link"/>
    <origin rpy="0 1.570795 0" xyz="0.032 0 0"/>
    <axis xyz="0 0 1"/>
    <child link="right_ankle_lateral_link"/>
    <limit effort="10" lower="-0.7" upper="0.7" velocity="1.0"/>
  </joint>
  <link name="right_ankle_lateral_link">
    <visual>
      <geometry>
        <mesh filename="file:///mnt/STORAGE/Dropbox/Personal/Programming/Bioloid/CAD/BPF-BU_FCD-Conv_BDR-Col.dae" scale="0.1 0.1 0.1"/>
      </geometry>
      <origin rpy="-1.570795 0 0" xyz="0 0 -0.05"/>
    </visual>
    <visual>
      <geometry>
        <mesh filename="file:///mnt/STORAGE/Dropbox/Personal/Programming/Bioloid/CAD/FP04-F5_FCD-Conv_BDR-Col.dae" scale="0.1 0.1 0.1"/>
      </geometry>
      <origin rpy="-1.570795 3.14159 0" xyz="0 0 -0.0153"/>
    </visual>
    <collision name="right_ankle_lateral_collision">
      <origin xyz="0 0.009 -0.016"/>
      <geometry>
        <box size="0.029 0.0405 0.083"/>
      </geometry>
    </collision>
    <inertial>
      <origin xyz="0 0 0"/>
      <mass value="1.0"/>
      <inertia ixx="0.001" ixy="0.0" ixz="0.0" iyy="0.001" iyz="0.0" izz="0.001"/>
    </inertial>
  </link>
  <!-- Right ankle lateral to foot -->
  <joint name="right_foot_joint" type="fixed">
    <parent link="right_ankle_lateral_link"/>
    <origin rpy="0 0 0" xyz="0 0 0"/>
    <child link="right_foot_link"/>
  </joint>
  <link name="right_foot_link">
    <visual>
      <geometry>
        <mesh filename="file:///mnt/STORAGE/Dropbox/Personal/Programming/Bioloid/CAD/FP04-F12_FCD-Conv_BDR-Col.dae" scale="0.1 0.1 0.1"/>
      </geometry>
      <origin rpy="0 -1.570795 0" xyz="-0.008 0.0235 -0.016"/>
    </visual>
    <collision name="right_foot_collision">
      <origin xyz="-0.008 0.0277 -0.016"/>
      <geometry>
        <box size="0.061 0.009 0.101"/>
      </geometry>
    </collision>
    <inertial>
      <origin xyz="0 0 0"/>
      <mass value="1.0"/>
      <inertia ixx="0.001" ixy="0.0" ixz="0.0" iyy="0.001" iyz="0.0" izz="0.001"/>
    </inertial>
  </link>
  <!-- Left ankle swing to ankle lateral -->
  <joint name="left_ankle_lateral_joint" type="revolute">
    <parent link="left_ankle_swing_link"/>
    <origin rpy="0 1.570795 0" xyz="-0.032 0 0"/>
    <axis xyz="0 0 1"/>
    <child link="left_ankle_lateral_link"/>
    <limit effort="10" lower="-0.7" upper="0.7" velocity="1.0"/>
  </joint>
  <link name="left_ankle_lateral_link">
    <visual>
      <geometry>
        <mesh filename="file:///mnt/STORAGE/Dropbox/Personal/Programming/Bioloid/CAD/BPF-BU_FCD-Conv_BDR-Col.dae" scale="0.1 0.1 0.1"/>
      </geometry>
      <origin rpy="1.570795 0 0" xyz="0 0 0.05"/>
    </visual>
    <visual>
      <geometry>
        <mesh filename="file:///mnt/STORAGE/Dropbox/Personal/Programming/Bioloid/CAD/FP04-F5_FCD-Conv_BDR-Col.dae" scale="0.1 0.1 0.1"/>
      </geometry>
      <origin rpy="1.570795 3.14159 0" xyz="0 0 0.0153"/>
    </visual>
    <collision name="left_ankle_lateral_collision">
      <origin xyz="0 -0.009 0.016"/>
      <geometry>
        <box size="0.029 0.0405 0.083"/>
      </geometry>
    </collision>
    <inertial>
      <origin xyz="0 0 0"/>
      <mass value="1.0"/>
      <inertia ixx="0.001" ixy="0.0" ixz="0.0" iyy="0.001" iyz="0.0" izz="0.001"/>
    </inertial>
  </link>
  <!-- Left ankle lateral to foot -->
  <joint name="left_foot_joint" type="fixed">
    <parent link="left_ankle_lateral_link"/>
    <origin rpy="0 0 0" xyz="0 0 0"/>
    <child link="left_foot_link"/>
  </joint>
  <link name="left_foot_link">
    <visual>
      <geometry>
        <mesh filename="file:///mnt/STORAGE/Dropbox/Personal/Programming/Bioloid/CAD/FP04-F12_FCD-Conv_BDR-Col.dae" scale="0.1 0.1 0.1"/>
      </geometry>
      <origin rpy="3.14159 1.570795 0" xyz="0.008 -0.0235 0.016"/>
    </visual>
    <collision name="left_foot_collision">
      <origin xyz="0.008 -0.0277 0.016"/>
      <geometry>
        <box size="0.061 0.009 0.101"/>
      </geometry>
    </collision>
    <inertial>
      <origin xyz="0 0 0"/>
      <mass value="1.0"/>
      <inertia ixx="0.001" ixy="0.0" ixz="0.0" iyy="0.001" iyz="0.0" izz="0.001"/>
    </inertial>
  </link>
</robot>
