<?xml version="1.0"?>
<robot xmlns:xacro="http://www.ros.org/wiki/xacro" name="bioloid">
<!-- Modified Bioloid Comprehensive humanoid, with CM-5 replaced by PC and custom sensors -->

<xacro:property name="pi" value="3.14159"/>
<xacro:property name="cad_dir" value="file:///mnt/STORAGE/Dropbox/Personal/Programming/Bioloid/CAD"/>
<!-- Typically, STL/DAE model units are in mm, but RViz units are in m, hence models must be scaled down by 1000. -->
<xacro:macro name="default_geometry" params="cad_file suffix:=_FCD-Conv_BDR-Col extension:=dae">
    <geometry>
        <mesh filename="${cad_dir}/${cad_file}${suffix}.${extension}" scale="0.001 0.001 0.001"/>
    </geometry>
</xacro:macro>
<xacro:macro name="z_rot">
    <axis xyz="0 0 1"/>
</xacro:macro>
<!-- <xacro:macro name="shoulder_swing_joint" params="prefix reflect x"> -->
<xacro:macro name="shoulder_swing_joint" params="prefix reflect">
    <joint name="${prefix}_shoulder_swing_joint" type="revolute">
        <parent link="torso_link"/>
        <!-- <origin xyz="${reflect*(-0.032)} 0 0" rpy="0 ${reflect*(-pi/2)} ${x*pi}"/> -->
        <origin xyz="${reflect*(-0.032)} 0 0" rpy="${reflect*(-pi/2)} 0 ${reflect*(pi/2)}"/>
        <xacro:z_rot/>
        <child link="${prefix}_shoulder_swing_link"/>
        <limit lower="${-pi}" upper="${pi}" effort="10" velocity="1.0"/>
    </joint>
</xacro:macro>
<xacro:macro name="shoulder_lateral_joint" params="prefix reflect">
    <joint name="${prefix}_shoulder_lateral_joint" type="revolute">
        <parent link="${prefix}_shoulder_swing_link"/>
        <!-- <origin xyz="${reflect*(-0.014)} 0 ${reflect*0.044}" rpy="${-pi/2} 0 0"/> -->
        <origin xyz="${reflect*(-0.014)} 0 ${reflect*0.044}" rpy="${-pi/2} ${pi/2} 0"/>
        <xacro:z_rot/>
        <child link="${prefix}_upper_arm_link"/>
        <limit lower="${-pi}" upper="${pi}" effort="10" velocity="1.0"/>
    </joint>
</xacro:macro>
<xacro:macro name="elbow_joint" params="prefix reflect">
    <joint name="${prefix}_elbow_joint" type="revolute">
        <parent link="${prefix}_upper_arm_link"/>
        <origin xyz="${reflect*-0.0675} 0 0" rpy="0 0 0"/>
        <xacro:z_rot/>
        <child link="${prefix}_lower_arm_link"/>
        <limit lower="${-1.77}" upper="${1.77}" effort="10" velocity="1.0"/>
    </joint>
</xacro:macro>
<xacro:macro name="hand_joint" params="prefix">
    <joint name="${prefix}_hand_joint" type="fixed">
        <parent link="${prefix}_lower_arm_link"/>
        <origin xyz="0 0 0" rpy="0 0 0"/>
        <child link="${prefix}_hand_link"/>
    </joint>
</xacro:macro>
<xacro:macro name="hip_twist_joint" params="prefix reflect rotatex rotatez">
    <joint name="${prefix}_hip_twist_joint" type="revolute">
        <parent link="torso_link"/>
        <origin xyz="${reflect*(-0.033)} 0.016 -0.0655" rpy="${rotatex*pi} 0 ${rotatez*pi}"/>
        <xacro:z_rot/>
        <child link="${prefix}_hip_twist_link"/>
        <limit lower="${-pi/4}" upper="${pi/4}" effort="10" velocity="1.0"/>
    </joint>
</xacro:macro>
<xacro:macro name="hip_lateral_joint" params="prefix reflect">
    <joint name="${prefix}_hip_lateral_joint" type="revolute">
        <parent link="${prefix}_hip_twist_link"/>
        <origin xyz="0 -0.0153 ${reflect*0.05}" rpy="${reflect*pi/2} 0 0"/>
        <xacro:z_rot/>
        <child link="${prefix}_hip_lateral_link"/>
        <limit lower="${-0.3}" upper="${0.3}" effort="10" velocity="1.0"/>
    </joint>
</xacro:macro>
<xacro:macro name="hip_swing_joint" params="prefix reflect rotatex">
    <joint name="${prefix}_hip_swing_joint" type="revolute">
        <parent link="${prefix}_hip_lateral_link"/>
        <origin xyz="0 0 ${reflect*(-0.032)}" rpy="${rotatex*pi} ${-pi/2} 0"/>
        <xacro:z_rot/>
        <child link="${prefix}_upper_leg_link"/>
        <limit lower="${-pi/2}" upper="${pi/2}" effort="10" velocity="1.0"/>
    </joint>
</xacro:macro>
<xacro:macro name="knee_joint" params="prefix reflect">
    <joint name="${prefix}_knee_joint" type="revolute">
        <parent link="${prefix}_upper_leg_link"/>
        <origin xyz="${reflect*0.0145} ${reflect*0.075} 0" rpy="0 0 0"/>
        <xacro:z_rot/>
        <child link="${prefix}_lower_leg_link"/>
        <limit lower="${-pi}" upper="${0}" effort="10" velocity="1.0"/>
    </joint>
</xacro:macro>
<xacro:macro name="ankle_swing_joint" params="prefix reflect">
    <joint name="${prefix}_ankle_swing_joint" type="revolute">
        <parent link="${prefix}_lower_leg_link"/>
        <origin xyz="${reflect*-0.0145} ${reflect*0.071} 0" rpy="0 0 0"/>
        <xacro:z_rot/>
        <child link="${prefix}_ankle_swing_link"/>
        <limit lower="${-0.45}" upper="${pi/2}" effort="10" velocity="1.0"/>
    </joint>
</xacro:macro>
<xacro:macro name="ankle_lateral_joint" params="prefix reflect">
    <joint name="${prefix}_ankle_lateral_joint" type="revolute">
        <parent link="${prefix}_ankle_swing_link"/>
        <origin xyz="${reflect*0.032} 0 0" rpy="0 ${pi/2} 0"/>
        <xacro:z_rot/>
        <child link="${prefix}_ankle_lateral_link"/>
        <limit lower="${-0.7}" upper="${0.7}" effort="10" velocity="1.0"/>
    </joint>
</xacro:macro>
<xacro:macro name="foot_joint" params="prefix">
    <joint name="${prefix}_foot_joint" type="fixed">
        <parent link="${prefix}_ankle_lateral_link"/>
        <origin xyz="0 0 0" rpy="0 0 0"/>
        <child link="${prefix}_foot_link"/>
    </joint>
</xacro:macro>

<!-- IMU -->
<joint name="imu_to_base_joint" type="fixed">
    <parent link="imu_link"/>
    <origin xyz="0.01 0 0.0788" rpy="0 0 0"/>
    <child link="base_link"/>
</joint>
<link name="imu_link">
    <visual>
        <geometry>
            <box size="0.04 0.02 0.005"/>
        </geometry>
        <material name="green">
            <color rgba="0.0 1.0 0.0 1.0"/>
        </material>
    </visual>
    <!--<inertial>
      <origin xyz="0 0 0"/>
      <mass value="1.0"/>
      <inertia  ixx="0.001" ixy="0.0"  ixz="0.0"  iyy="0.001"  iyz="0.0"  izz="0.001"/>
    </inertial>-->
</link>

<!-- Base -->
<joint name="base_to_torso_joint" type="fixed">
    <parent link="base_link"/>
    <origin xyz="0 0 0" rpy="0 0 ${pi/2}"/>
    <child link="torso_link"/>
</joint>
<link name="base_link">
</link>

<!-- Camera -->
<!--<joint name="camera_joint" type="fixed">
    <origin xyz="0 0 0.075" rpy="${pi/2} 0 ${pi/2}"/>
    <parent link="base_link"/>
    <child link="camera_link"/>
</joint>
<link name="camera_link">-->
    <!--<visual>
        <geometry>
            <box size="0.01 0.01 0.01"/>
        </geometry>
        <material name="black">
            <color rgba="0.0 0.0 0.0 1.0"/>
        </material>
    </visual>
    <inertial>
      <origin xyz="0 0 0"/>
      <mass value="1.0"/>
      <inertia  ixx="0.001" ixy="0.0"  ixz="0.0"  iyy="0.001"  iyz="0.0"  izz="0.001"/>
    </inertial>-->
<!--</link>-->

<!-- Head -->
<joint name="head_joint" type="fixed">
    <origin xyz="0 0 0.058" rpy="0 0 0"/>
    <parent link="base_link"/>
    <child link="head_link"/>
</joint>
<link name="head_link">
    <visual>
        <xacro:default_geometry cad_file="FP04-F5"/>
        <origin xyz="0 0 0" rpy="${pi/2} 0 ${-pi/2}"/>
    </visual>
    <visual>
        <xacro:default_geometry cad_file="FP04-F10"/>
        <origin xyz="0 0 -0.0342" rpy="${pi/2} 0 ${-pi/2}"/>
    </visual>
    <visual>
        <xacro:default_geometry cad_file="RaspPiB_plus_3d_step_V10" suffix="_FCD-Conv"/>
        <origin xyz="-0.008 0 0" rpy="${-pi/2} 0 ${-pi/2}"/>
    </visual>
    <collision name="head_bracket_collision">
        <origin xyz="-0.009 0 0"/>
        <geometry>
            <box size="0.0405 0.029 0.083"/>
        </geometry>
    </collision>
    <collision name="head_spacer_collision">
        <origin xyz="0 0 -0.0342"/>
        <geometry>
            <box size="0.0251 0.0383 0.0041"/>
        </geometry>
    </collision>
    <collision name="raspberry_pi_collision">
        <origin xyz="-0.0023 -0.0008 0.0008"/>
        <geometry>
            <box size="0.021 0.087 0.058"/>
        </geometry>
    </collision>
    <inertial>
      <origin xyz="0 0 0"/>
      <mass value="1.0"/>
      <inertia  ixx="0.001" ixy="0.0"  ixz="0.0"  iyy="0.001"  iyz="0.0"  izz="0.001"/>
    </inertial>
</link>

<!-- CPU case -->
<joint name="cpu_case_joint" type="fixed">
    <origin xyz="0 0 0.058" rpy="0 0 0"/>
    <parent link="base_link"/>
    <child link="cpu_case_link"/>
</joint>
<link name="cpu_case_link">
    <visual>
        <origin xyz="0 0 0"/>
        <geometry>
            <box size="0.026 0.092 0.063"/>
        </geometry>
        <material name="smoke_grey_transp">
            <color rgba="0.2 0.2 0.2 0.8"/>
        </material>
    </visual>
    <collision name="cpu_case_collision">
        <origin xyz="0 0 0"/>
        <geometry>
            <box size="0.026 0.092 0.063"/>
        </geometry>
    </collision>
    <inertial>
      <origin xyz="0 0 0"/>
      <mass value="1.0"/>
      <inertia  ixx="0.001" ixy="0.0"  ixz="0.0"  iyy="0.001"  iyz="0.0"  izz="0.001"/>
    </inertial>
</link>

<!-- Torso -->
<link name="torso_link">
    <visual>
        <xacro:default_geometry cad_file="BPF-CHEST-F"/>
        <origin rpy="${pi/2} 0 0"/>
    </visual>
    <visual>
        <xacro:default_geometry cad_file="BPF-CHEST-B"/>
        <origin rpy="${pi/2} 0 0"/>
    </visual>
    <!--<visual>
        <xacro:default_geometry cad_file="CM-5"/>
        <origin xyz="0 0.032 -0.015" rpy="0 ${pi} 0"/>
    </visual>-->
    <!-- Sensor 100 -->
    <!--<visual>
        <xacro:default_geometry cad_file="AX-S1"/>
        <origin xyz="0 0 0.025" rpy="${-pi/2} 0 ${pi}"/>
    </visual>-->
    <visual>
        <xacro:default_geometry cad_file="Backpack-DX"/>
        <origin xyz="0 0.019 -0.0145" rpy="0 0 ${pi/2}"/>
    </visual>
    <visual>
        <xacro:default_geometry cad_file="Battery-Turnigy-2200mAh"/>
        <origin xyz="0 0.032 -0.008" rpy="0 ${pi/2} ${pi/2}"/>
    </visual>
    <!-- Motor 1 -->
    <visual>
        <xacro:default_geometry cad_file="AX-12"/>
        <origin xyz="-0.032 0 0" rpy="${pi/2} 0 ${-pi/2}"/>
    </visual>
    <!-- Motor 2 -->
    <visual>
        <xacro:default_geometry cad_file="AX-12"/>
        <origin xyz="0.032 0 0" rpy="${pi/2} 0 ${pi/2}"/>
    </visual>
    <visual>
        <xacro:default_geometry cad_file="FP04-F8"/>
        <origin xyz="0 0.0255 -0.0465" rpy="${-pi/2} 0 ${pi/2}"/>
    </visual>
    <visual>
        <xacro:default_geometry cad_file="FP04-F8"/>
        <origin xyz="0 0.0255 -0.0843" rpy="${pi/2} 0 ${pi/2}"/>
    </visual>
    <!-- Motor 7 -->
    <visual>
        <xacro:default_geometry cad_file="AX-12"/>
        <origin xyz="-0.033 0.016 -0.0655" rpy="0 ${pi} 0"/>
    </visual>
    <!-- Motor 8 -->
    <visual>
        <xacro:default_geometry cad_file="AX-12"/>
        <origin xyz="0.033 0.016 -0.0655" rpy="0 ${pi} 0"/>
    </visual>
    <!--<collision name="head_collision">
        <origin xyz="0 0.0122 0.035"/>
        <geometry>
		    <box size="0.033 0.054 0.044"/>
        </geometry>
    </collision>-->
    <collision name="torso_collision_top">
        <origin xyz="0 0.0075 -0.015"/>
        <geometry>
		    <box size="0.103 0.066 0.0635"/>
        </geometry>
    </collision>


    <collision name="Backpack-DX_collision">
        <origin xyz="0 0.041 -0.0145"/>
        <geometry>
            <box size="0.09 0.0441 0.058"/>
        </geometry>
    </collision>
    <collision name="Battery-Turnigy-2200mAh_collision">
        <origin xyz="0 0.04425 -0.008"/>
        <geometry>
            <box size="0.108 0.0246 0.036"/>
        </geometry>
    </collision>
    <collision name="Battery-Turnigy-2200mAh_collision_lead">
        <origin xyz="-0.0515 0.04425 -0.031"/>
        <geometry>
            <box size="0.0041 0.0246 0.01"/>
        </geometry>
    </collision>


    <collision name="torso_collision_bottom">
        <origin xyz="0 0.00625 -0.0648"/>
        <geometry>
		    <box size="0.099 0.065 0.043"/>
        </geometry>
    </collision>
    <inertial>
      <origin xyz="0 0 0"/>
      <mass value="1.0"/>
      <inertia  ixx="0.001" ixy="0.0"  ixz="0.0"  iyy="0.001"  iyz="0.0"  izz="0.001"/>
    </inertial>
</link>

<!-- Torso to right shoulder -->
<xacro:shoulder_swing_joint prefix="right" reflect="1"/>
<link name="right_shoulder_swing_link">
    <visual>
        <xacro:default_geometry cad_file="FP04-F1"/>
        <origin xyz="-0.014 0 0.044" rpy="0 ${pi} ${-pi/2}"/>
    </visual>
    <collision name="right_shoulder_collision">
        <origin xyz="-0.006 0 0.0375"/>
        <geometry>
		    <box size="0.039 0.052 0.036"/>
        </geometry>
    </collision>
    <inertial>
      <origin xyz="0 0 0"/>
      <mass value="1.0"/>
      <inertia  ixx="0.001" ixy="0.0"  ixz="0.0"  iyy="0.001"  iyz="0.0"  izz="0.001"/>
    </inertial>
</link>

<!-- Torso to left shoulder -->
<xacro:shoulder_swing_joint prefix="left" reflect="-1"/>
<link name="left_shoulder_swing_link">
    <visual>
        <xacro:default_geometry cad_file="FP04-F1"/>
        <origin xyz="0.014 0 -0.044" rpy="0 0 ${pi/2}"/>
    </visual>
    <collision name="left_shoulder_collision">
        <origin xyz="0.006 0 -0.0375"/>
        <geometry>
		    <box size="0.039 0.052 0.036"/>
        </geometry>
    </collision>
    <inertial>
      <origin xyz="0 0 0"/>
      <mass value="1.0"/>
      <inertia  ixx="0.001" ixy="0.0"  ixz="0.0"  iyy="0.001"  iyz="0.0"  izz="0.001"/>
    </inertial>
</link>

<!-- Right shoulder to upper arm -->
<xacro:shoulder_lateral_joint prefix="right" reflect="1"/>
<link name="right_upper_arm_link">
    <visual>
        <xacro:default_geometry cad_file="AX-12"/>
        <origin xyz="0 0 0" rpy="${pi} 0 ${pi/2}"/>
    </visual>
    <visual>
        <xacro:default_geometry cad_file="BPF-BU"/>
        <origin xyz="0 0 0.0185" rpy="${pi/2} 0 0"/>
    </visual>
    <visual>
        <xacro:default_geometry cad_file="BPF-WA"/>
        <origin xyz="0 0 0.019" rpy="${pi/2} 0 0"/>
    </visual>
    <visual>
        <xacro:default_geometry cad_file="FP04-F3"/>
        <origin xyz="-0.0415 0 0" rpy="0 0 ${-pi/2}"/>
    </visual>
    <visual>
        <xacro:default_geometry cad_file="FP04-F2"/>
        <origin xyz="-0.0675 0 0" rpy="0 ${pi/2} 0"/>
    </visual>
    <collision name="right_upper arm_collision_proximal">
        <origin xyz="-0.0148 0 0"/>
        <geometry>
		    <box size="0.054 0.033 0.044"/>
        </geometry>
    </collision>
    <collision name="right_upper arm_collision_distal">
        <origin xyz="-0.0555 0 0"/>
        <geometry>
		    <box size="0.047 0.033 0.052"/>
        </geometry>
    </collision>
    <inertial>
      <origin xyz="0 0 0"/>
      <mass value="1.0"/>
      <inertia  ixx="0.001" ixy="0.0"  ixz="0.0"  iyy="0.001"  iyz="0.0"  izz="0.001"/>
    </inertial>
</link>

<!-- Left shoulder to upper arm -->
<xacro:shoulder_lateral_joint prefix="left" reflect="-1"/>
<link name="left_upper_arm_link">
    <visual>
        <xacro:default_geometry cad_file="AX-12"/>
        <origin xyz="0 0 0" rpy="0 0 ${pi/2}"/>
    </visual>
    <visual>
        <xacro:default_geometry cad_file="BPF-BU"/>
        <origin xyz="0 0 -0.0185" rpy="${-pi/2} 0 0"/>
    </visual>
    <visual>
        <xacro:default_geometry cad_file="BPF-WA"/>
        <origin xyz="0 0 -0.019" rpy="${-pi/2} 0 0"/>
    </visual>
    <visual>
        <xacro:default_geometry cad_file="FP04-F3"/>
        <origin xyz="0.0415 0 0" rpy="0 0 ${pi/2}"/>
    </visual>
    <visual>
        <xacro:default_geometry cad_file="FP04-F2"/>
        <origin xyz="0.0675 0 0" rpy="0 ${-pi/2} 0"/>
    </visual>
    <collision name="left_upper arm_collision_proximal">
        <origin xyz="0.0148 0 0"/>
        <geometry>
		    <box size="0.054 0.033 0.044"/>
        </geometry>
    </collision>
    <collision name="left_upper arm_collision_distal">
        <origin xyz="0.0555 0 0"/>
        <geometry>
		    <box size="0.047 0.033 0.052"/>
        </geometry>
    </collision>
    <inertial>
      <origin xyz="0 0 0"/>
      <mass value="1.0"/>
      <inertia  ixx="0.001" ixy="0.0"  ixz="0.0"  iyy="0.001"  iyz="0.0"  izz="0.001"/>
    </inertial>
</link>

<!-- Right upper arm to lower arm -->
<xacro:elbow_joint prefix="right" reflect="1"/>
<link name="right_lower_arm_link">
    <!-- Motor 5 -->
    <visual>
        <xacro:default_geometry cad_file="AX-12"/>
        <origin xyz="0 0 0" rpy="${pi} 0 ${pi/2}"/>
    </visual>
    <visual>
        <xacro:default_geometry cad_file="BPF-BU"/>
        <origin xyz="0 0 0.0185" rpy="${pi/2} 0 0"/>
    </visual>
    <visual>
        <xacro:default_geometry cad_file="BPF-WA"/>
        <origin xyz="0 0 0.019" rpy="${pi/2} 0 0"/>
    </visual>
    <visual>
        <xacro:default_geometry cad_file="FP04-F3"/>
        <origin xyz="-0.0415 0 0" rpy="0 0 ${-pi/2}"/>
    </visual>
    <collision name="right_lower_arm_collision">
        <origin xyz="-0.0135 0 0"/>
        <geometry>
		    <box size="0.051 0.033 0.044"/>
        </geometry>
    </collision>
    <inertial>
      <origin xyz="0 0 0"/>
      <mass value="1.0"/>
      <inertia  ixx="0.001" ixy="0.0"  ixz="0.0"  iyy="0.001"  iyz="0.0"  izz="0.001"/>
    </inertial>
</link>

<!-- Right lower arm to hand -->
<xacro:hand_joint prefix="right"/>
<link name="right_hand_link">
    <visual>
        <xacro:default_geometry cad_file="FP04-F11"/>
        <origin xyz="-0.0415 0 0" rpy="${-pi} ${pi/2} 0"/>
    </visual>
    <collision name="right_palm_collision">
        <origin xyz="-0.039 0 0"/>
        <geometry>
		    <box size="0.0131 0.0265 0.044"/>
        </geometry>
    </collision>
    <collision name="right_fingers_collision">
        <origin xyz="-0.0701 -0.0077 0"/>
        <geometry>
		    <box size="0.0575 0.0175 0.035"/>
        </geometry>
    </collision>
    <inertial>
      <origin xyz="0 0 0"/>
      <mass value="1.0"/>
      <inertia  ixx="0.001" ixy="0.0"  ixz="0.0"  iyy="0.001"  iyz="0.0"  izz="0.001"/>
    </inertial>
</link>

<!-- Left upper arm to lower arm -->
<xacro:elbow_joint prefix="left" reflect="-1"/>
<link name="left_lower_arm_link">
    <!-- Motor 6 -->
    <visual>
        <xacro:default_geometry cad_file="AX-12"/>
        <origin xyz="0 0 0" rpy="0 0 ${pi/2}"/>
    </visual>
    <visual>
        <xacro:default_geometry cad_file="BPF-BU"/>
        <origin xyz="0 0 -0.0185" rpy="${-pi/2} 0 0"/>
    </visual>
    <visual>
        <xacro:default_geometry cad_file="BPF-WA"/>
        <origin xyz="0 0 -0.019" rpy="${-pi/2} 0 0"/>
    </visual>
    <visual>
        <xacro:default_geometry cad_file="FP04-F3"/>
        <origin xyz="0.0415 0 0" rpy="0 0 ${pi/2}"/>
    </visual>
    <collision name="left_lower_arm_collision">
        <origin xyz="0.017 0 0"/>
        <geometry>
		    <box size="0.058 0.033 0.044"/>
        </geometry>
    </collision>
    <inertial>
      <origin xyz="0 0 0"/>
      <mass value="1.0"/>
      <inertia  ixx="0.001" ixy="0.0"  ixz="0.0"  iyy="0.001"  iyz="0.0"  izz="0.001"/>
    </inertial>
</link>

<!-- Left lower arm to hand -->
<xacro:hand_joint prefix="left"/>
<link name="left_hand_link">
    <visual>
        <xacro:default_geometry cad_file="FP04-F11"/>
        <origin xyz="0.0415 0 0" rpy="0 ${pi/2} 0"/>
    </visual>
    <collision name="left_palm_collision">
        <origin xyz="0.039 0 0"/>
        <geometry>
		    <box size="0.0131 0.0265 0.044"/>
        </geometry>
    </collision>
    <collision name="left_fingers_collision">
        <origin xyz="0.0701 0.0077 0"/>
        <geometry>
		    <box size="0.0575 0.0175 0.035"/>
        </geometry>
    </collision>
    <inertial>
      <origin xyz="0 0 0"/>
      <mass value="1.0"/>
      <inertia  ixx="0.001" ixy="0.0"  ixz="0.0"  iyy="0.001"  iyz="0.0"  izz="0.001"/>
    </inertial>
</link>

<!-- Torso to right hip twist -->
<xacro:hip_twist_joint prefix="right" reflect="1" rotatex="1" rotatez="0"/>
<link name="right_hip_twist_link">
    <visual>
        <xacro:default_geometry cad_file="FP04-F5"/>
        <origin xyz="0 0 0.05" rpy="${pi} 0 0"/>
    </visual>
    <collision name="right_hip_twist_collision">
        <origin xyz="0 0.0008 0.041"/>
        <geometry>
		    <box size="0.029 0.083 0.0405"/>
        </geometry>
    </collision>
    <inertial>
      <origin xyz="0 0 0"/>
      <mass value="1.0"/>
      <inertia  ixx="0.001" ixy="0.0"  ixz="0.0"  iyy="0.001"  iyz="0.0"  izz="0.001"/>
    </inertial>
</link>

<!-- Torso to left hip twist -->
<xacro:hip_twist_joint prefix="left" reflect="-1" rotatex="0" rotatez="1"/>
<link name="left_hip_twist_link">
    <visual>
        <xacro:default_geometry cad_file="FP04-F5"/>
        <origin xyz="0 0 -0.05" rpy="0 0 ${pi}"/>
    </visual>
    <collision name="left_hip_twist_collision">
        <origin xyz="0 0.0008 -0.041"/>
        <geometry>
		    <box size="0.029 0.083 0.0405"/>
        </geometry>
    </collision>
    <inertial>
      <origin xyz="0 0 0"/>
      <mass value="1.0"/>
      <inertia  ixx="0.001" ixy="0.0"  ixz="0.0"  iyy="0.001"  iyz="0.0"  izz="0.001"/>
    </inertial>
</link>

<!-- Right hip twist to hip lateral -->
<xacro:hip_lateral_joint prefix="right" reflect="1"/>
<link name="right_hip_lateral_link">
    <!-- Motor 9 -->
    <visual>
        <xacro:default_geometry cad_file="AX-12"/>
        <origin xyz="0 0 0" rpy="0 0 ${pi}"/>
    </visual>
    <visual>
        <xacro:default_geometry cad_file="FP04-F6"/>
        <origin xyz="-0.019 0.0145 0.016" rpy="0 ${-pi/2} ${-pi/2}"/>
    </visual>
    <visual>
        <xacro:default_geometry cad_file="FP04-F6"/>
        <origin xyz="0.019 0.0145 0.016" rpy="0 ${-pi/2} ${pi/2}"/>
    </visual>
    <!-- Motor 11 -->
    <visual>
        <xacro:default_geometry cad_file="AX-12"/>
        <origin xyz="0 0 -0.032" rpy="${pi} ${-pi/2} 0"/>
    </visual>
    <visual>
        <xacro:default_geometry cad_file="BPF-BU"/>
        <origin xyz="0 0 -0.05" rpy="${-pi/2} 0 0"/>
    </visual>
    <visual>
        <xacro:default_geometry cad_file="FP04-F7"/>
        <origin xyz="0 0.0145 -0.051" rpy="${pi/2} 0 ${-pi/2}"/>
    </visual>
    <collision name="right_hip_lateral_collision">
        <origin xyz="0 0.0135 -0.0153"/>
        <geometry>
		    <box size="0.04 0.051 0.0721"/>
        </geometry>
    </collision>
    <inertial>
      <origin xyz="0 0 0"/>
      <mass value="1.0"/>
      <inertia  ixx="0.001" ixy="0.0"  ixz="0.0"  iyy="0.001"  iyz="0.0"  izz="0.001"/>
    </inertial>
</link>

<!-- Left hip twist to hip lateral -->
<xacro:hip_lateral_joint prefix="left" reflect="-1"/>
<link name="left_hip_lateral_link">
    <!-- Motor 10 -->
    <visual>
        <xacro:default_geometry cad_file="AX-12"/>
        <origin xyz="0 0 0" rpy="${pi} 0 0"/>
    </visual>
    <visual>
        <xacro:default_geometry cad_file="FP04-F6"/>
        <origin xyz="-0.019 0.0145 -0.016" rpy="0 ${pi/2} ${-pi/2}"/>
    </visual>
    <visual>
        <xacro:default_geometry cad_file="FP04-F6"/>
        <origin xyz="0.019 0.0145 -0.016" rpy="0 ${pi/2} ${pi/2}"/>
    </visual>
    <!-- Motor 12 -->
    <visual>
        <xacro:default_geometry cad_file="AX-12"/>
        <origin xyz="0 0 0.032" rpy="${pi} ${-pi/2} 0"/>
    </visual>
    <visual>
        <xacro:default_geometry cad_file="BPF-BU"/>
        <origin xyz="0 0 0.05" rpy="${pi/2} 0 0"/>
    </visual>
    <visual>
        <xacro:default_geometry cad_file="FP04-F7"/>
        <origin xyz="0 0.0145 0.051" rpy="${-pi/2} 0 ${-pi/2}"/>
    </visual>
    <collision name="left_hip_lateral_collision">
        <origin xyz="0 0.0135 0.0153"/>
        <geometry>
		    <box size="0.04 0.051 0.0721"/>
        </geometry>
    </collision>
    <inertial>
      <origin xyz="0 0 0"/>
      <mass value="1.0"/>
      <inertia  ixx="0.001" ixy="0.0"  ixz="0.0"  iyy="0.001"  iyz="0.0"  izz="0.001"/>
    </inertial>
</link>

<!-- Right hip lateral to upper leg -->
<xacro:hip_swing_joint prefix="right" reflect="1" rotatex="0"/>
<link name="right_upper_leg_link">
    <visual>
        <xacro:default_geometry cad_file="FP04-F4"/>
        <origin xyz="0 0 0" rpy="${-pi/2} ${pi/2} 0"/>
    </visual>
    <visual>
        <xacro:default_geometry cad_file="FP04-F1"/>
        <origin xyz="0.0145 0.075 0" rpy="${pi/2} ${-pi/2} 0"/>
    </visual>
    <collision name="right_upper_leg_proximal_collision">
        <origin xyz="0 0.0214 0"/>
        <geometry>
		    <box size="0.03 0.065 0.049"/>
        </geometry>
    </collision>
    <collision name="right_upper_leg_distal_collision">
        <origin xyz="0.0065 0.0675 0"/>
        <geometry>
		    <box size="0.04 0.0371 0.049"/>
        </geometry>
    </collision>
    <inertial>
      <origin xyz="0 0 0"/>
      <mass value="1.0"/>
      <inertia  ixx="0.001" ixy="0.0"  ixz="0.0"  iyy="0.001"  iyz="0.0"  izz="0.001"/>
    </inertial>
</link>

<!-- Left hip lateral to upper leg -->
<xacro:hip_swing_joint prefix="left" reflect="-1" rotatex="1"/>
<link name="left_upper_leg_link">
    <visual>
        <xacro:default_geometry cad_file="FP04-F4"/>
        <origin xyz="0 0 0" rpy="${pi/2} ${pi/2} 0"/>
    </visual>
    <visual>
        <xacro:default_geometry cad_file="FP04-F1"/>
        <origin xyz="-0.0145 -0.075 0" rpy="${-pi/2} ${-pi/2} 0"/>
    </visual>
    <collision name="left_upper_leg_proximal_collision">
        <origin xyz="0 -0.0214 0"/>
        <geometry>
		    <box size="0.03 0.065 0.049"/>
        </geometry>
    </collision>
    <collision name="left_upper_leg_distal_collision">
        <origin xyz="-0.0065 -0.0675 0"/>
        <geometry>
		    <box size="0.04 0.0371 0.049"/>
        </geometry>
    </collision>
    <inertial>
      <origin xyz="0 0 0"/>
      <mass value="1.0"/>
      <inertia  ixx="0.001" ixy="0.0"  ixz="0.0"  iyy="0.001"  iyz="0.0"  izz="0.001"/>
    </inertial>
</link>

<!-- Right upper leg to lower leg -->
<xacro:knee_joint prefix="right" reflect="1"/>
<link name="right_lower_leg_link">
    <!-- Motor 13 -->
    <visual>
        <xacro:default_geometry cad_file="AX-12"/>
        <origin xyz="0 0 0" rpy="0 ${pi} ${-pi/2}"/>
    </visual>
    <visual>
        <xacro:default_geometry cad_file="FP04-F3"/>
        <origin xyz="-0.0145 0.019 0" rpy="0 0 ${pi}"/>
    </visual>
    <visual>
        <xacro:default_geometry cad_file="FP04-F4"/>
        <origin xyz="-0.0145 0.071 0" rpy="${pi/2} ${-pi/2} 0"/>
    </visual>
    <collision name="right_lower_leg_proximal_collision">
        <origin xyz="-0.0135 0 0"/>
        <geometry>
		    <box size="0.051 0.033 0.044"/>
        </geometry>
    </collision>
    <collision name="right_lower_leg_distal_collision">
        <origin xyz="-0.0145 0.0492 0"/>
        <geometry>
		    <box size="0.03 0.067 0.049"/>
        </geometry>
    </collision>
    <inertial>
      <origin xyz="0 0 0"/>
      <mass value="1.0"/>
      <inertia  ixx="0.001" ixy="0.0"  ixz="0.0"  iyy="0.001"  iyz="0.0"  izz="0.001"/>
    </inertial>
</link>

<!-- Left upper leg to lower leg -->
<xacro:knee_joint prefix="left" reflect="-1"/>
<link name="left_lower_leg_link">
    <!-- Motor 14 -->
    <visual>
        <xacro:default_geometry cad_file="AX-12"/>
        <origin xyz="0 0 0" rpy="0 0 ${pi/2}"/>
    </visual>
    <visual>
        <xacro:default_geometry cad_file="FP04-F3"/>
        <origin xyz="0.0145 -0.019 0" rpy="0 0 0"/>
    </visual>
    <visual>
        <xacro:default_geometry cad_file="FP04-F4"/>
        <origin xyz="0.0145 -0.071 0" rpy="${-pi/2} ${-pi/2} 0"/>
    </visual>
    <collision name="left_lower_leg_proximal_collision">
        <origin xyz="0.0135 0 0"/>
        <geometry>
		    <box size="0.051 0.033 0.044"/>
        </geometry>
    </collision>
    <collision name="left_lower_leg_distal_collision">
        <origin xyz="0.0145 -0.0492 0"/>
        <geometry>
		    <box size="0.03 0.067 0.049"/>
        </geometry>
    </collision>
    <inertial>
      <origin xyz="0 0 0"/>
      <mass value="1.0"/>
      <inertia  ixx="0.001" ixy="0.0"  ixz="0.0"  iyy="0.001"  iyz="0.0"  izz="0.001"/>
    </inertial>
</link>

<!-- Right lower leg to ankle swing -->
<xacro:ankle_swing_joint prefix="right" reflect="1"/>
<link name="right_ankle_swing_link">
    <!-- Motor 15 -->
    <visual>
        <xacro:default_geometry cad_file="AX-12"/>
        <origin xyz="0 0 0" rpy="0 ${pi} 0"/>
    </visual>
    <visual>
        <xacro:default_geometry cad_file="FP04-F7"/>
        <origin xyz="-0.019 -0.0145 0" rpy="${pi} 0 ${pi/2}"/>
    </visual>
    <!-- Motor 17 -->
    <visual>
        <xacro:default_geometry cad_file="AX-12"/>
        <origin xyz="0.032 0 0" rpy="0 ${pi/2} 0"/>
    </visual>
    <visual>
        <xacro:default_geometry cad_file="FP04-F6"/>
        <origin xyz="0.048 -0.0145 0.019" rpy="${-pi/2} 0 0"/>
    </visual>
    <visual>
        <xacro:default_geometry cad_file="FP04-F6"/>
        <origin xyz="0.048 -0.0145 -0.019" rpy="${pi/2} 0 0"/>
    </visual>
    <collision name="right_ankle_swing_collision">
        <origin xyz="0.0167 -0.0135 0"/>
        <geometry>
		    <box size="0.0721 0.051 0.04"/>
        </geometry>
    </collision>
    <inertial>
      <origin xyz="0 0 0"/>
      <mass value="1.0"/>
      <inertia  ixx="0.001" ixy="0.0"  ixz="0.0"  iyy="0.001"  iyz="0.0"  izz="0.001"/>
    </inertial>
</link>

<!-- Left lower leg to ankle swing -->
<xacro:ankle_swing_joint prefix="left" reflect="-1"/>
<link name="left_ankle_swing_link">
    <!-- Motor 16 -->
    <visual>
        <xacro:default_geometry cad_file="AX-12"/>
        <origin xyz="0 0 0" rpy="0 0 ${pi}"/>
    </visual>
    <visual>
        <xacro:default_geometry cad_file="FP04-F7"/>
        <origin xyz="0.019 0.0145 0" rpy="${pi} 0 ${-pi/2}"/>
    </visual>
    <!-- Motor 18 -->
    <visual>
        <xacro:default_geometry cad_file="AX-12"/>
        <origin xyz="-0.032 0 0" rpy="${pi} ${pi/2} 0"/>
    </visual>
    <visual>
        <xacro:default_geometry cad_file="FP04-F6"/>
        <origin xyz="-0.048 0.0145 -0.019" rpy="${pi/2} 0 ${pi}"/>
    </visual>
    <visual>
        <xacro:default_geometry cad_file="FP04-F6"/>
        <origin xyz="-0.048 0.0145 0.019" rpy="${-pi/2} 0 ${pi}"/>
    </visual>
    <collision name="left_ankle_swing_collision">
        <origin xyz="-0.0167 0.0135 0"/>
        <geometry>
		    <box size="0.0721 0.051 0.04"/>
        </geometry>
    </collision>
    <inertial>
      <origin xyz="0 0 0"/>
      <mass value="1.0"/>
      <inertia  ixx="0.001" ixy="0.0"  ixz="0.0"  iyy="0.001"  iyz="0.0"  izz="0.001"/>
    </inertial>
</link>

<!-- Right ankle swing to ankle lateral -->
<xacro:ankle_lateral_joint prefix="right" reflect="1"/>
<link name="right_ankle_lateral_link">
    <visual>
        <xacro:default_geometry cad_file="BPF-BU"/>
        <origin xyz="0 0 -0.05" rpy="${-pi/2} 0 0"/>
    </visual>
    <visual>
        <xacro:default_geometry cad_file="FP04-F5"/>
        <origin xyz="0 0 -0.0153" rpy="${-pi/2} ${pi} 0"/>
    </visual>
    <collision name="right_ankle_lateral_collision">
        <origin xyz="0 0.009 -0.016"/>
        <geometry>
		    <box size="0.029 0.0405 0.083"/>
        </geometry>
    </collision>
    <inertial>
      <origin xyz="0 0 0"/>
      <mass value="1.0"/>
      <inertia  ixx="0.001" ixy="0.0"  ixz="0.0"  iyy="0.001"  iyz="0.0"  izz="0.001"/>
    </inertial>
</link>

<!-- Right ankle lateral to foot -->
<xacro:foot_joint prefix="right"/>
<link name="right_foot_link">
    <visual>
        <xacro:default_geometry cad_file="FP04-F12"/>
        <origin xyz="-0.008 0.0235 -0.016" rpy="0 ${-pi/2} 0"/>
    </visual>
    <collision name="right_foot_collision">
        <origin xyz="-0.008 0.0277 -0.016"/>
        <geometry>
		    <box size="0.061 0.009 0.101"/>
        </geometry>
    </collision>
    <inertial>
      <origin xyz="0 0 0"/>
      <mass value="1.0"/>
      <inertia  ixx="0.001" ixy="0.0"  ixz="0.0"  iyy="0.001"  iyz="0.0"  izz="0.001"/>
    </inertial>
</link>

<!-- Left ankle swing to ankle lateral -->
<xacro:ankle_lateral_joint prefix="left" reflect="-1"/>
<link name="left_ankle_lateral_link">
    <visual>
        <xacro:default_geometry cad_file="BPF-BU"/>
        <origin xyz="0 0 0.05" rpy="${pi/2} 0 0"/>
    </visual>
    <visual>
        <xacro:default_geometry cad_file="FP04-F5"/>
        <origin xyz="0 0 0.0153" rpy="${pi/2} ${pi} 0"/>
    </visual>
    <collision name="left_ankle_lateral_collision">
        <origin xyz="0 -0.009 0.016"/>
        <geometry>
		    <box size="0.029 0.0405 0.083"/>
        </geometry>
    </collision>
    <inertial>
      <origin xyz="0 0 0"/>
      <mass value="1.0"/>
      <inertia  ixx="0.001" ixy="0.0"  ixz="0.0"  iyy="0.001"  iyz="0.0"  izz="0.001"/>
    </inertial>
</link>

<!-- Left ankle lateral to foot -->
<xacro:foot_joint prefix="left"/>
<link name="left_foot_link">
    <visual>
        <xacro:default_geometry cad_file="FP04-F12"/>
        <origin xyz="0.008 -0.0235 0.016" rpy="${pi} ${pi/2} 0"/>
    </visual>
    <collision name="left_foot_collision">
        <origin xyz="0.008 -0.0277 0.016"/>
        <geometry>
		    <box size="0.061 0.009 0.101"/>
        </geometry>
    </collision>
    <inertial>
      <origin xyz="0 0 0"/>
      <mass value="1.0"/>
      <inertia  ixx="0.001" ixy="0.0"  ixz="0.0"  iyy="0.001"  iyz="0.0"  izz="0.001"/>
    </inertial>
</link>

</robot>
